Workbook
Name countsheets: get.work(1)&T(NOW())
Name countshhets: get,workbook(1)&T(NOW())
Name _Toc191645711: 상환비율!$C$2
Name _Toc191645712: 상환비율!$C$3
Name a: #REF!
Name aaaa: #REF!
Name al: #REF!
Name b: #REF!
Name bb: #REF!
Name cash: #REF!
Name d: #REF!
Name dd: #REF!
Name ddd: #REF!
Name dddd: #REF!
Name ff: #REF!
Name gg: #REF!
Name hhh: #REF!
Name hj: BlankMacro1
Name kkk: #REF!
Name M: #REF!
Name qw: #REF!
Name qwe: #REF!
Name RT: #REF!,#REF!,#REF!
Name sample: #REF!
Name ss: #REF!
Name V: #REF!
Name w: #REF!
Name ㄱㄱ: #REF!
Name 가가: #REF!
Name 강: #REF!
Name ㄴ: BlankMacro1
Name ㄴㄴ: #REF!
Name ㄹ: "SK 텔레콤"
Name ㅁㅁ: {"Client Name or Project Name"}
Name 매출: #REF!
Name 미수금: #REF!
Name ㅂ: #REF!
Name ㅂㅂ: {"Project Green"}
Name ㅅ: "사이삼 정보통신"
Name 산출근거: #REF!
Name ㅇ: #REF!
Name ㅇㅇ: BlankMacro1
Name 원가: #N/A
Name ㅈ: "좋은사람들"
Name 잡이익: #REF!

Sheet 2026(예정)
B1: ■ 2026년 매각요청 대상주유소
B3: NO | C3: 구분 | E3: 지역 | F3: 주유소명 | G3: 상세주소 | H3: 대지면적(㎡) | I3: 대지면적(평) | J3: 지역지구 | L3: 보증금 | M3: 월 임대료 | N3: 임차인 | R3: 매매대금(원) | S3: 장부가 | V3: 매입가 | Y3: 감정평가(담보) | Z3: 상환비율 | AA3: 회수 원본 | AB3: 입찰공고 ('26.10.14)
J4: 용도지역 | K4: 지구단위계획 | N4: HDO | O4: SKN | P4: 기타 | Q4: 비고 | S4: 토지 | T4: 건축물 등 | U4: 계 | V4: 토지 | W4: 건축물 등 | X4: 계 | Y4: 계
B5: 1 | C5: 신규 | D5: 46093 | E5: 인천 | F5: 공단1 | G5: 인천 남동구 남동대로 367 | H5: 3302.1 | I5: =H5/3.3058 | J5: 일반공업 | K5: 해당 | L5: 707000000 | M5: 27426000 | N5: 23599000 | O5: 1869000 | P5: 1958000 | Q5: - | R5: 0 | S5: 6.8208067e+09 | T5: 513000000 | U5: 7.3741072e+09 | V5: 6454000000 | W5: 513000000 | X5: 6967000000 | Y5: =VLOOKUP(F5,'주유소별가격(담보)'!$C$4:$H$158,6,0) | Z5: 0.495 | AA5: =U5-L5-Y5*Z5 | AB5: No.1 | AD5: 매각주유소(담보가) | AE5: =Y49/1000000
B6: 2 | E6: 인천 | F6: 공단2 | G6: 인천 남동구 앵고개로 463 | H6: 3635.7 | I6: =H6/3.3058 | J6: 일반공업 | K6: 해당 | L6: 891209000 | M6: 35544276 | N6: 29520000 | O6: 1988000 | P6: 4036276 | Q6: - | R6: 0 | S6: 8.3109446e+09 | T6: 873000000 | U6: 9.2544639e+09 | V6: 7864000000 | W6: 873000000 | X6: 8737000000 | Y6: =VLOOKUP(F6,'주유소별가격(담보)'!$C$4:$H$158,6,0) | Z6: 0.495 | AA6: =U6-L6-Y6*Z6 | AB6: No.2 | AD6: 매각시 회수원본 | AE6: =(AA49)/1000000
B7: 3 | E7: 경기 | F7: 프리미엄셀프 | G7: 경기 화성시 삼성1로 231 | H7: 1676.2 | I7: =H7/3.3058 | J7: 근린상업 | K7: 해당 | L7: 688000000 | M7: 27861000 | N7: 24275000 | O7: 3586000 | P7: 0 | Q7: - | R7: 0 | S7: 7.0324238e+09 | T7: 526000000 | U7: 7.6024792e+09 | V7: 6654000000 | W7: 526000000 | X7: 7180000000 | Y7: =VLOOKUP(F7,'주유소별가격(담보)'!$C$4:$H$158,6,0) | Z7: 0.495 | AA7: =U7-L7-Y7*Z7 | AB7: No.6
B8: 4 | E8: 경기 | F8: 송탄제일셀프 | G8: 경기 평택시 송탄로 81 | H8: 1173 | I8: =H8/3.3058 | J8: 제1종일반 | K8: - | L8: 299000000 | M8: 10488000 | N8: 10488000 | O8: 0 | P8: 0 | Q8: - | R8: 0 | S8: 3.0121595e+09 | T8: 267000000 | U8: 3.3002958e+09 | V8: 2850000000 | W8: 267000000 | X8: 3117000000 | Y8: =VLOOKUP(F8,'주유소별가격(담보)'!$C$4:$H$158,6,0) | Z8: 0.495 | AA8: =U8-L8-Y8*Z8 | AB8: No.7
B9: 5 | E9: 인천 | F9: 산곡셀프 | G9: 인천 부평구 원적로 417 | H9: 1291.9 | I9: =H9/3.3058 | J9: 제2종일반 | K9: - | L9: 397000000 | M9: 17407000 | N9: 14041000 | O9: 3366000 | P9: 0 | Q9: - | R9: 0 | S9: 3.7241018e+09 | T9: 623000000 | U9: 4.3889372e+09 | V9: 3524000000 | W9: 623000000 | X9: 4147000000 | Y9: =VLOOKUP(F9,'주유소별가격(담보)'!$C$4:$H$158,6,0) | Z9: 0.495 | AA9: =U9-L9-Y9*Z9 | AB9: No.4 | AD9: 주유소 매각 | AE9: 0.364 | AF9: 0.1 | AG9: 0.2 | AH9: 0.3 | AI9: 0.4 | AJ9: 0.5 | AK9: 0.6 | AL9: 0.7 | AM9: 0.8 | AN9: 0.9 | AO9: 1
B10: 6 | E10: 충남 | F10: 잠홍셀프 | G10: 충남 서산시 서해로 3602 | H10: 1168 | I10: =H10/3.3058 | J10: 자연녹지 | K10: 해당 | L10: 102000000 | M10: 3553000 | N10: 3553000 | O10: 0 | P10: 0 | Q10: - | R10: 0 | S10: 9.7576949e+08 | T10: 147000000 | U10: 1.1325673e+09 | V10: 923000000 | W10: 147000000 | X10: 1070000000 | Y10: =VLOOKUP(F10,'주유소별가격(담보)'!$C$4:$H$158,6,0) | Z10: 0.385 | AA10: =U10-L10-Y10*Z10 | AB10: 미포함 | AD10: DF타워 우선주 원본 | AE10: 373 | AF10: 373 | AG10: 373 | AH10: 373 | AI10: 373 | AJ10: 373 | AK10: 373 | AL10: 373 | AM10: 373 | AN10: 373 | AO10: 373
B11: 7 | E11: 경남 | F11: 양산대로 | G11: 경남 양산시 상북면 양산대로 1229 | H11: 1850 | I11: =H11/3.3058 | J11: 준공업 | K11: - | L11: 254000000 | M11: 8289000 | N11: 8289000 | O11: 0 | P11: 0 | Q11: - | R11: 0 | S11: 2.5220935e+09 | T11: 173000000 | U11: 2.7087711e+09 | V11: 2386000000 | W11: 173000000 | X11: 2559000000 | Y11: =VLOOKUP(F11,'주유소별가격(담보)'!$C$4:$H$158,6,0) | Z11: 0.385 | AA11: =U11-L11-Y11*Z11 | AB11: No.17 | AD11: 주유소 회수 원본 | AE11: =$AE$6*AE$9/100 | AF11: =$AE$6*AF$9/100 | AG11: =$AE$6*AG$9/100 | AH11: =$AE$6*AH$9/100 | AI11: =$AE$6*AI$9/100 | AJ11: =$AE$6*AJ$9/100 | AK11: =$AE$6*AK$9/100 | AL11: =$AE$6*AL$9/100 | ... AO11: =$AE$6*AO$9/100
B12: 8 | E12: 경남 | F12: 극동셀프 | G12: 경남 창원시 마산회원구 삼호로 258 | H12: 2082.4 | I12: =H12/3.3058 | J12: 준주거 | K12: - | L12: 263000000 | M12: 9304000 | N12: 9304000 | O12: 0 | P12: 0 | Q12: - | R12: 0 | S12: 2.3705485e+09 | T12: 505000000 | U12: 2.9117197e+09 | V12: 2243000000 | W12: 505000000 | X12: 2748000000 | Y12: =VLOOKUP(F12,'주유소별가격(담보)'!$C$4:$H$158,6,0) | Z12: 0.385 | AA12: =U12-L12-Y12*Z12 | AB12: No.18 | AD12: 재투자 재원(합계) | AE12: =SUM(AE10:AE11) | AF12: =SUM(AF10:AF11) | AG12: =SUM(AG10:AG11) | AH12: =SUM(AH10:AH11) | AI12: =SUM(AI10:AI11) | AJ12: =SUM(AJ10:AJ11) | AK12: =SUM(AK10:AK11) | AL12: =SUM(AL10:AL11) | ... AO12: =SUM(AO10:AO11)
B13: 9 | E13: 충북 | F13: 조양 | G13: 충북 제천시 내토로 333 | H13: 4886 | I13: =H13/3.3058 | J13: 제2종일반 | K13: - | L13: 359000000 | M13: 12011000 | N13: 12011000 | O13: 0 | P13: 0 | Q13: - | R13: 0 | S13: 3.4154135e+09 | T13: 512000000 | U13: 3.9684859e+09 | V13: 3232000000 | W13: 512000000 | X13: 3744000000 | Y13: =VLOOKUP(F13,'주유소별가격(담보)'!$C$4:$H$158,6,0) | Z13: 0.385 | AA13: =U13-L13-Y13*Z13 | AB13: No.11 | AD13: 추가 담보대출 | AE13: =MAX(AE15-SUM(AE10:AE11),) | AF13: =MAX(AF15-SUM(AF10:AF11),) | AG13: =MAX(AG15-SUM(AG10:AG11),) | AH13: =MAX(AH15-SUM(AH10:AH11),) | AI13: =MAX(AI15-SUM(AI10:AI11),) | AJ13: =MAX(AJ15-SUM(AJ10:AJ11),) | AK13: =MAX(AK15-SUM(AK10:AK11),) | AL13: =MAX(AL15-SUM(AL10:AL11),) | ... AO13: =MAX(AO15-SUM(AO10:AO11),)
B14: 10 | D14: 46170 | E14: 강원 | F14: 춘천 | G14: 강원 춘천시 춘천로 412 (후평동) | H14: 1316 | I14: =IF(H14="","",H14/3.3058) | J14: 제2종일반 | K14: - | L14: 146000000 | M14: =N14+O14+P14 | N14: 4906000 | O14: 0 | P14: 0 | Q14: - | R14: 0 | S14: 1.2564703e+09 | T14: 333000000 | U14: 1.6141832e+09 | V14: 1189000000 | W14: 333000000 | X14: 1522000000 | Y14: =VLOOKUP(F14,'주유소별가격(담보)'!$C$4:$H$158,6,0) | Z14: 0.385 | AA14: =U14-L14-Y14*Z14 | AB14: 미포함 | AD14: 확보재원 | AE14: =SUM(AE12:AE13) | AF14: =SUM(AF12:AF13) | AG14: =SUM(AG12:AG13) | AH14: =SUM(AH12:AH13) | AI14: =SUM(AI12:AI13) | AJ14: =SUM(AJ12:AJ13) | AK14: =SUM(AK12:AK13) | AL14: =SUM(AL12:AL13) | ... AO14: =SUM(AO12:AO13)
B15: 11 | E15: 경기 | F15: 효행로셀프 | G15: 경기 화성시 효행로 767 (안녕동) | H15: 415 | I15: =IF(H15="","",H15/3.3058) | J15: 준주거 | K15: - | L15: 92000000 | M15: =N15+O15+P15 | N15: 3299000 | O15: 0 | P15: 0 | Q15: - | R15: 0 | S15: 8.0939624e+08 | T15: 180000000 | U15: 1.0019103e+09 | V15: 766000000 | W15: 180000000 | X15: 946000000 | Y15: =VLOOKUP(F15,'주유소별가격(담보)'!$C$4:$H$158,6,0) | Z15: 0.495 | AA15: =U15-L15-Y15*Z15 | AB15: 미포함 | AD15: 우선주 매입액 | AE15: =SUMIF($AF$9:$AO$9,$AE$9,$AF15:$AO15) | AF15: =74000/100 | AG15: =74000/100 | AH15: =74000/100 | AI15: =74000/100 | AJ15: =74000/100 | AK15: =74000/100 | AL15: =74000/100 | AM15: =74000/100 | ... AO15: =74000/100
B16: 12 | E16: 경기 | F16: 민락셀프 | G16: 경기 의정부시 충의로 91 (용현동) | H16: 1413 | I16: =IF(H16="","",H16/3.3058) | J16: 제1종일반 | K16: - | L16: 466000000 | M16: =N16+O16+P16 | N16: 16409000 | O16: 2927000 | P16: 0 | Q16: - | R16: 0 | S16: 4.6437917e+09 | T16: 475000000 | U16: 5.1536337e+09 | V16: 4394000000 | W16: 475000000 | X16: 4869000000 | Y16: =VLOOKUP(F16,'주유소별가격(담보)'!$C$4:$H$158,6,0) | Z16: 0.495 | AA16: =U16-L16-Y16*Z16 | AB16: 미포함 | AD16: 주유소 LTV | AE16: =SUMIF($AF$9:$AO$9,$AE$9,$AF16:$AO16) | AF16: =(SUM($AG$21:$AG$23)+AF$13)/($AE$21-AF$17) | AG16: =(SUM($AG$21:$AG$23)+AG$13)/($AE$21-AG$17) | AH16: =(SUM($AG$21:$AG$23)+AH$13)/($AE$21-AH$17) | AI16: =(SUM($AG$21:$AG$23)+AI$13)/($AE$21-AI$17) | AJ16: =(SUM($AG$21:$AG$23)+AJ$13)/($AE$21-AJ$17) | AK16: =(SUM($AG$21:$AG$23)+AK$13)/($AE$21-AK$17) | AL16: =(SUM($AG$21:$AG$23)+AL$13)/($AE$21-AL$17) | AM16: =(SUM($AG$21:$AG$23)+AM$13)/($AE$21-AM$17) | ... AO16: =(SUM($AG$21:$AG$23)+AO$13)/($AE$21-AO$17)
B17: 13 | E17: 경기 | F17: 성복현대 | G17: 경기 용인시 수지구 수지로 137 (성복동) | H17: 1084 | I17: =IF(H17="","",H17/3.3058) | J17: 제2종일반 | K17: - | L17: 559000000 | M17: =N17+O17+P17 | N17: 19793000 | O17: 0 | P17: 0 | Q17: - | R17: 0 | S17: 5.761252e+09 | T17: 386000000 | U17: 6.1729271e+09 | V17: 5451000000 | W17: 386000000 | X17: 5837000000 | Y17: =VLOOKUP(F17,'주유소별가격(담보)'!$C$4:$H$158,6,0) | Z17: 0.495 | AA17: =U17-L17-Y17*Z17 | AB17: 미포함 | AD17: 담보가 차감 | AE17: =SUMIF($AF$9:$AO$9,$AE$9,$AF17:$AO17) | AF17: =$AE$5*AF$9/100 | AG17: =$AE$5*AG$9/100 | AH17: =$AE$5*AH$9/100 | AI17: =$AE$5*AI$9/100 | AJ17: =$AE$5*AJ$9/100 | AK17: =$AE$5*AK$9/100 | AL17: =$AE$5*AL$9/100 | AM17: =$AE$5*AM$9/100 | ... AO17: =$AE$5*AO$9/100
B18: 14 | E18: 경기 | F18: 새광주셀프 | G18: 경기 광주시 경충대로 1515 (쌍령동) | H18: 1442 | I18: =IF(H18="","",H18/3.3058) | J18: 자연녹지 | K18: - | L18: 285000000 | M18: =N18+O18+P18 | N18: 9558000 | O18: 0 | P18: 0 | Q18: - | R18: 0 | S18: 2.3875543e+09 | T18: 718000000 | U18: 3.1478843e+09 | V18: 2259000000 | W18: 718000000 | X18: 2977000000 | Y18: =VLOOKUP(F18,'주유소별가격(담보)'!$C$4:$H$158,6,0) | Z18: 0.495 | AA18: =U18-L18-Y18*Z18 | AB18: No.8
B19: 15 | E19: 충북 | F19: 제천대로셀프 | G19: 충북 제천시 의림대로 226 (장전동) | H19: 1382.7 | I19: =IF(H19="","",H19/3.3058) | J19: 준주거 | K19: - | L19: 189000000 | M19: =N19+O19+P19 | N19: 6682000 | O19: 0 | P19: 0 | Q19: - | R19: 0 | S19: 1.6882727e+09 | T19: 378000000 | U19: 2.0937573e+09 | V19: 1597000000 | W19: 378000000 | X19: 1975000000 | Y19: =VLOOKUP(F19,'주유소별가격(담보)'!$C$4:$H$158,6,0) | Z19: 0.385 | AA19: =U19-L19-Y19*Z19 | AB19: No.10
B20: 16 | E20: 경기 | F20: 둔전셀프 | G20: 경기 용인시 처인구 포곡읍 포곡로 177 | H20: 1304 | I20: =IF(H20="","",H20/3.3058) | J20: 제2종일반 | K20: - | L20: 251000000 | M20: =N20+O20+P20 | N20: 8881000 | O20: 0 | P20: 0 | Q20: - | R20: 0 | S20: 2.1675802e+09 | T20: 566000000 | U20: 2.7705926e+09 | V20: 2051000000 | W20: 566000000 | X20: 2617000000 | Y20: =VLOOKUP(F20,'주유소별가격(담보)'!$C$4:$H$158,6,0) | Z20: 0.495 | AA20: =U20-L20-Y20*Z20 | AB20: No.5 | AD20: 주유소 자산(리파이낸싱)
B21: 17 | E21: 인천 | F21: 부평공단셀프 | G21: 인천 부평구 부평대로 262 (갈산동) | H21: 1826.9 | I21: =IF(H21="","",H21/3.3058) | J21: 준주거 | K21: 해당 | L21: 608000000 | M21: =N21+O21+P21 | N21: 20385000 | O21: 2901000 | P21: 0 | Q21: - | R21: 0 | S21: 6.2893975e+09 | T21: 392000000 | U21: 6.7102631e+09 | V21: 5951000000 | W21: 392000000 | X21: 6343000000 | Y21: =VLOOKUP(F21,'주유소별가격(담보)'!$C$4:$H$158,6,0) | Z21: 0.495 | AA21: =U21-L21-Y21*Z21 | AB21: No.3 | AD21: 담보가 | AE21: =1012489803.48/100000 | AF21: 선순위 | AG21: =458883427.36395/100000
B22: 18 | E22: 대구 | F22: 경대셀프 | G22: 대구 북구 중앙대로 601 (침산동) | H22: 1460 | I22: =IF(H22="","",H22/3.3058) | J22: 근린상업 | K22: 해당 | L22: 545000000 | M22: =N22+O22+P22 | N22: 18270000 | O22: 2764000 | P22: 0 | Q22: - | R22: 0 | S22: 5.4142978e+09 | T22: 568000000 | U22: 6.029025e+09 | V22: 5123000000 | W22: 568000000 | X22: 5691000000 | Y22: =VLOOKUP(F22,'주유소별가격(담보)'!$C$4:$H$158,6,0) | Z22: 0.44 | AA22: =U22-L22-Y22*Z22 | AB22: No.14 | AD22: 매각자산차감 | AE22: =-AE17 | AF22: 후순위 | AG22: 200
B23: 19 | E23: 충북 | F23: 교대셀프 | G23: 충북 청주시 서원구 청남로2005번길 2 (분평동) | H23: 3164 | I23: =IF(H23="","",H23/3.3058) | J23: 제2종일반 | K23: - | L23: 602000000 | M23: =N23+O23+P23 | N23: 20215000 | O23: 1996000 | P23: 0 | Q23: - | R23: 0 | S23: 6.3138588e+09 | T23: 308000000 | U23: 6.6451742e+09 | V23: 5974000000 | W23: 308000000 | X23: 6282000000 | Y23: =VLOOKUP(F23,'주유소별가격(담보)'!$C$4:$H$158,6,0) | Z23: 0.385 | AA23: =U23-L23-Y23*Z23 | AB23: No.12 | AF23: 주식담보대출 | AG23: 900 | AH23: =SUM(AG21:AG23)/SUM(AE21:AE22)
B24: 20 | E24: 대구 | F24: 남대구IC셀프 | G24: 대구 달서구 성서공단로 372 (월성동) | H24: 2216 | I24: =IF(H24="","",H24/3.3058) | J24: 일반공업 | K24: - | L24: 352000000 | M24: =N24+O24+P24 | N24: 12434000 | O24: 0 | P24: 0 | Q24: - | R24: 0 | S24: 3.5395587e+09 | T24: 326000000 | U24: 3.8916959e+09 | V24: 3349000000 | W24: 326000000 | X24: 3675000000 | Y24: =VLOOKUP(F24,'주유소별가격(담보)'!$C$4:$H$158,6,0) | Z24: 0.44 | AA24: =U24-L24-Y24*Z24 | AB24: No.13 | AF24: 추가대출 | AG24: =AE13 | AH24: =SUM(AG21:AG24)/SUM(AE21:AE23) | AI24: =AH24=AE16
B25: 21 | E25: 경북 | F25: 새화랑 | G25: 경북 경주시 초당길 103 (동천동) | H25: 2390.6 | I25: =IF(H25="","",H25/3.3058) | J25: 제2종일반 | K25: - | L25: 274000000 | M25: =N25+O25+P25 | N25: 9727000 | O25: 2977000 | P25: 0 | Q25: - | R25: 0 | S25: 2.7433418e+09 | T25: 264000000 | U25: 3.0282184e+09 | V25: 2596000000 | W25: 264000000 | X25: 2860000000 | Y25: =VLOOKUP(F25,'주유소별가격(담보)'!$C$4:$H$158,6,0) | Z25: 0.385 | AA25: =U25-L25-Y25*Z25 | AB25: No.15 | AF25: 보증금 | AG25: =85088196.6126504/100000
B26: 22 | E26: 대전 | F26: 노은 | G26: 대전 유성구 노은동로 79 (노은동) | H26: 1322.9 | I26: =IF(H26="","",H26/3.3058) | J26: 준주거 | K26: 해당 | L26: 321000000 | M26: =N26+O26+P26 | N26: 11334000 | O26: 3612000 | P26: 0 | Q26: - | R26: 0 | S26: 3.2305142e+09 | T26: 294000000 | U26: 3.5471189e+09 | V26: 3057000000 | W26: 294000000 | X26: 3351000000 | Y26: =VLOOKUP(F26,'주유소별가격(담보)'!$C$4:$H$158,6,0) | Z26: 0.44 | AA26: =U26-L26-Y26*Z26 | AB26: No.9
B27: 23 | E27: 경남 | F27: 밀양현대 | G27: 경남 밀양시 밀양대로 1811 (삼문동) | H27: 1497 | I27: =IF(H27="","",H27/3.3058) | J27: 제2종일반 | K27: - | L27: 194000000 | M27: =N27+O27+P27 | N27: 6513000 | O27: 1480000 | P27: 0 | Q27: - | R27: 0 | S27: 1.8209611e+09 | T27: 307000000 | U27: 2.1506528e+09 | V27: 1723000000 | W27: 307000000 | X27: 2030000000 | Y27: =VLOOKUP(F27,'주유소별가격(담보)'!$C$4:$H$158,6,0) | Z27: 0.385 | AA27: =U27-L27-Y27*Z27 | AB27: No.19
B28: 24 | E28: 경북 | F28: 열린 | G28: 경북 포항시 남구 연일읍 연일로 168 | H28: 2141 | I28: =IF(H28="","",H28/3.3058) | J28: 준주거 | K28: - | L28: 190000000 | M28: =N28+O28+P28 | N28: 6344000 | O28: 0 | P28: 0 | Q28: - | R28: 0 | S28: 1.9489776e+09 | T28: 138000000 | U28: 2.0984356e+09 | V28: 1844000000 | W28: 138000000 | X28: 1982000000 | Y28: =VLOOKUP(F28,'주유소별가격(담보)'!$C$4:$H$158,6,0) | Z28: 0.385 | AA28: =U28-L28-Y28*Z28 | AB28: No.16
B29: 신규 소계 | H29: =SUM(H5:H28) | I29: =SUM(I5:I28) | L29: =SUM(L5:L28) | M29: =SUM(M5:M28) | N29: =SUM(N5:N28) | O29: =SUM(O5:O28) | P29: =SUM(P5:P28) | S29: =SUM(S5:S28) | T29: =SUM(T5:T28) | U29: =SUM(U5:U28) | V29: =SUM(V5:V28) | W29: =SUM(W5:W28) | X29: =SUM(X5:X28) | Y29: =SUM(Y5:Y28) | AA29: =SUM(AA5:AA28) | AB29: =COUNTIF(AB5:AB28,"No.*")
B30: 1 | C30: 미매각 | E30: 경기 | F30: 마평현대셀프 | G30: 경기도 용인시 처인구 중부대로 1560 | H30: 1314 | I30: =H30/3.3058 | J30: 자연녹지 | K30: - | L30: 254000000 | M30: 8413000 | N30: 8413000 | O30: - | P30: - | Q30: - | R30: 0 | S30: 2.4849954e+09 | T30: 306000000 | U30: 2.8102044e+09 | V30: 2351000000 | W30: 306000000 | X30: 2657000000 | Y30: =VLOOKUP(F30,'주유소별가격(담보)'!$C$4:$H$158,6,0) | Z30: 0.495 | AA30: =U30-L30-Y30*Z30 | AB30: 미포함
B31: 2 | E31: 인천 | F31: 서인천셀프 | G31: 인천광역시 서구 서곶로 346 | H31: 1660 | I31: =H31/3.3058 | J31: 제2종일반주거 | K31: - | L31: 510500000 | M31: 20170000 | N31: 16587000 | O31: 3050000 | P31: 533000 | Q31: - | R31: 0 | S31: 4.7239644e+09 | T31: 784000000 | U31: 5.5654601e+09 | V31: 4470000000 | W31: 784000000 | X31: 5254000000 | Y31: =VLOOKUP(F31,'주유소별가격(담보)'!$C$4:$H$158,6,0) | Z31: 0.495 | AA31: =U31-L31-Y31*Z31 | AB31: 미포함
B32: 3 | E32: 인천 | F32: 미추홀셀프 | G32: 인천광역시 미추홀구 인주대로 394 | H32: 1062 | I32: =H32/3.3058 | J32: 준주거 | K32: - | L32: 391000000 | M32: 13663000 | N32: 13663000 | O32: - | P32: - | Q32: - | R32: 0 | S32: 4.0265915e+09 | T32: 271000000 | U32: 4.3156537e+09 | V32: 3810000000 | W32: 271000000 | X32: 4081000000 | Y32: =VLOOKUP(F32,'주유소별가격(담보)'!$C$4:$H$158,6,0) | Z32: 0.495 | AA32: =U32-L32-Y32*Z32 | AB32: 미포함
B33: 4 | E33: 대전 | F33: 동원 | G33: 대전광역시 동구 옥천로 355-3 | H33: 433 | I33: =H33/3.3058 | J33: 자연녹지 | K33: - | L33: 82200000 | M33: 2750000 | N33: 2750000 | O33: - | P33: - | Q33: - | R33: 0 | S33: 6.9028292e+08 | T33: 164000000 | U33: 8.6678017e+08 | V33: 672000000 | W33: 164000000 | X33: 836000000 | Y33: =VLOOKUP(F33,'주유소별가격(담보)'!$C$4:$H$158,6,0) | Z33: 0.44 | AA33: =U33-L33-Y33*Z33 | AB33: 미포함
B34: 5 | E34: 대구 | F34: 송현셀프 | G34: 대구광역시 달서구 구마로 219 | H34: 1546 | I34: =H34/3.3058 | J34: 근린상업, 제2종일반주거 | K34: - | L34: 452000000 | M34: 17756000 | N34: 14663000 | O34: 2688000 | P34: 405000 | Q34: - | R34: 0 | S34: 4.3595106e+09 | T34: 492000000 | U34: 4.8904542e+09 | V34: 4125000000 | W34: 492000000 | X34: 4617000000 | Y34: =VLOOKUP(F34,'주유소별가격(담보)'!$C$4:$H$158,6,0) | Z34: 0.44 | AA34: =U34-L34-Y34*Z34 | AB34: 미포함
B35: 6 | E35: 대구 | F35: 중앙셀프 | G35: 대구광역시 북구 동북로 315 | H35: 1823 | I35: =H35/3.3058 | J35: 제2종일반주거 | K35: - | L35: 579000000 | M35: 22526000 | N35: 20163000 | O35: 2363000 | P35: - | Q35: - | R35: 0 | S35: 5.624504e+09 | T35: 725000000 | U35: 6.4035111e+09 | V35: 5322000000 | W35: 725000000 | X35: 6047000000 | Y35: =VLOOKUP(F35,'주유소별가격(담보)'!$C$4:$H$158,6,0) | Z35: 0.44 | AA35: =U35-L35-Y35*Z35 | AB35: 미포함
B36: 7 | E36: 경남 | F36: 고현셀프 | G36: 경상남도 거제시 고현동 963-4 | H36: 1653 | I36: =H36/3.3058 | J36: 제2종일반주거 | K36: - | L36: 419000000 | M36: 14667000 | N36: 14667000 | O36: - | P36: - | Q36: - | R36: 0 | S36: 4.1575154e+09 | T36: 444000000 | U36: 4.6335735e+09 | V36: 3934000000 | W36: 444000000 | X36: 4378000000 | Y36: =VLOOKUP(F36,'주유소별가격(담보)'!$C$4:$H$158,6,0) | Z36: 0.385 | AA36: =U36-L36-Y36*Z36 | AB36: 미포함
B37: 8 | E37: 경남 | F37: 진주셀프 | G37: 경상남도 진주시 평거동 194-2 | H37: 1163 | I37: =H37/3.3058 | J37: 일반상업 | K37: 해당 | L37: 437000000 | M37: 17583000 | N37: 15250000 | O37: 2333000 | P37: - | Q37: - | R37: 0 | S37: 4.4186913e+09 | T37: 379000000 | U37: 4.8235552e+09 | V37: 4181000000 | W37: 379000000 | X37: 4560000000 | Y37: =VLOOKUP(F37,'주유소별가격(담보)'!$C$4:$H$158,6,0) | Z37: 0.385 | AA37: =U37-L37-Y37*Z37 | AB37: 미포함
B38: 9 | E38: 경기 | F38: 드림셀프 | G38: 경기도 양주시 광사동 659-3 | H38: 1411 | I38: =H38/3.3058 | J38: 제2종일반주거 | K38: 해당 | L38: 274000000 | M38: 9083000 | N38: 9083000 | O38: - | P38: - | Q38: - | R38: 0 | S38: 2.8234815e+09 | T38: 192000000 | U38: 3.0317228e+09 | V38: 2672000000 | W38: 192000000 | X38: 2864000000 | Y38: =VLOOKUP(F38,'주유소별가격(담보)'!$C$4:$H$158,6,0) | Z38: 0.495 | AA38: =U38-L38-Y38*Z38 | AB38: 미포함
B39: 10 | E39: 경기 | F39: 향남현대 | G39: 경기도 화성군 향남면 제암리 286-4 | H39: 2031 | I39: =H39/3.3058 | J39: 자연녹지 | K39: - | L39: 258000000 | M39: 8583000 | N39: 8583000 | O39: - | P39: - | Q39: - | R39: 0 | S39: 2.6812271e+09 | T39: 158000000 | U39: 2.8497751e+09 | V39: 2537000000 | W39: 158000000 | X39: 2695000000 | Y39: =VLOOKUP(F39,'주유소별가격(담보)'!$C$4:$H$158,6,0) | Z39: 0.495 | AA39: =U39-L39-Y39*Z39 | AB39: 미포함
B40: 11 | E40: 경기 | F40: 중동대로셀프 | G40: 경기도 부천시 원미구 약대동 192-3 | H40: 2000 | I40: =H40/3.3058 | J40: 근린상업 | K40: 해당 | L40: 719000000 | M40: 21967000 | N40: 16250000 | O40: 5717000 | P40: - | Q40: - | R40: 0 | S40: 7.4545088e+09 | T40: 454000000 | U40: 7.9420205e+09 | V40: 7054000000 | W40: 454000000 | X40: 7508000000 | Y40: =VLOOKUP(F40,'주유소별가격(담보)'!$C$4:$H$158,6,0) | Z40: 0.495 | AA40: =U40-L40-Y40*Z40 | AB40: 미포함
B41: 12 | E41: 대구 | F41: 공단제일 | G41: 대구광역시 달서구 호산동 720-2 | H41: 2140 | I41: =H41/3.3058 | J41: 일반상업 | K41: - | L41: 1109000000 | M41: 43141111 | N41: 23833000 | O41: 1758000 | P41: 17550111 | Q41: - | R41: 0 | S41: 1.1667068e+10 | T41: 543000000 | U41: 1.225636e+10 | V41: 11040000000 | W41: 543000000 | X41: 11583000000 | Y41: =VLOOKUP(F41,'주유소별가격(담보)'!$C$4:$H$158,6,0) | Z41: 0.44 | AA41: =U41-L41-Y41*Z41 | AB41: 미포함
...

Sheet 2026(완료)
B2: No. | C2: 지역 | D2: 주유소명 | E2: 상세주소 | F2: 담보가 | I2: 상환비율 | J2: 차입금 반환 | K2: 보증금 | L2: 매매대금 | O2: 소유권이전
F3: 토지 | G3: 건축물 등 | H3: 계 | L3: 합 계 | M3: 계약금 | N3: 잔금 | O3: 계약체결일 | P3: 잔금일 | Q3: 회수 원본
B4: 1 | C4: 경기 | D4: 동양 | E4: 경기 안산시 단원구 신길동 1743 | F4: 3340590000 | G4: 25493000 | H4: 3366083000 | I4: 0.495 | J4: 1666211085 | K4: 223000000 | L4: 2955000000 | M4: 295500000 | N4: 2659500000 | O4: 2026.04.01. | P4: 2026.04.30. | Q4: 770288915
B5: 2 | C5: 광주 | D5: 빛고을로셀프 | E5: 광주 북구 용두동 1043-1 | F5: 1559520000 | G5: 123891370 | H5: 1683411370 | I5: 0.44 | J5: 7.40701e+08 | K5: 138000000 | L5: 1200000000 | M5: 120000000 | N5: 1080000000 | O5: 2026.04.01. | P5: 2026.04.30. | Q5: 2.01299e+08
B6: 3 | C6: 경북 | D6: 진량현대 | E6: 경북 경산시 진량읍 신상리 1083 | F6: 2433190000 | G6: 212060200 | H6: 2645250200 | I6: 0.385 | J6: 1018421327 | K6: 237000000 | L6: 2000000000 | M6: 200000000 | N6: 1800000000 | O6: 2026.04.14. | P6: 2026.05.15. | Q6: 544578673 | R6: 148
B7: 4 | C7: 광주 | D7: 양산 | E7: 광주 북구 양산동 610-17 | F7: 2641320000 | G7: 46143350 | H7: 2687463350 | I7: 0.44 | J7: 1182483874 | K7: 192000000 | L7: 1800000000 | M7: 180000000 | N7: 1620000000 | O7: 2026.04.01. | P7: 2026.06.10 | Q7: 245516126
B8: 5 | C8: 부산 | D8: 낙동로 | E8: 부산 사상구 삼락동 409-1 | F8: 7138354000 | G8: 248388680 | H8: 7386742680 | I8: 0.44 | J8: 3.2501668e+09 | K8: 625000000 | L8: 6700000000 | N8: 6700000000 | O8: 2025.04.02 | P8: 2026.06.29 | Q8: 2.8248332e+09
B9: 6 | C9: 경기 | D9: 남문 | E9: 경기 성남시 수정구 태평동 6539 외 4필지 | F9: 2142884500 | G9: 92253010 | H9: 2235137510 | I9: 0.495 | J9: 1.1063931e+09 | K9: 186000000 | L9: 1500000000 | M9: 150000000 | N9: 1350000000 | O9: 2026.04.01. | P9: 2026.07.01. | Q9: 57606933
B10: 7 | C10: 광주 | D10: 장덕셀프 | E10: 광주 광산구 장덕동 85-3 | F10: 2027810000 | G10: 127343310 | H10: 2155153310 | I10: 0.44 | J10: 9.4826746e+08 | K10: 119000000 | L10: 1300000000 | M10: 130000000 | N10: 1170000000 | O10: 2026.04.01. | P10: 2026.07.01. | Q10: 1.0273254e+08
B11: 8 | C11: 경기 | D11: 죽전현대셀프 | E11: 경기 용인시 수지구 죽전동 889 (용구대로 2751) | F11: 8782200000 | G11: 373725100 | H11: 9155925100 | I11: 0.495 | J11: 4.5321829e+09 | K11: 671000000 | L11: 7500000000 | M11: 750000000 | N11: 6750000000 | O11: 2026.05.11. | P11: 2026.07.13. | Q11: 1.5468171e+09
B12: 9 | C12: 인천 | D12: 유화셀프 | E12: 인천 계양구 효성동 206-9 | F12: 7311969000 | G12: 169466100 | H12: 7481435100 | I12: 0.495 | J12: 3.7033104e+09 | K12: 493000000 | L12: 5400000000 | M12: 270000000 | N12: 5130000000 | O12: 2026.04.14. | P12: 2026.07.14. | Q12: 9.3368963e+08
B13: 기 계약 합계 | Q13: 7.2273621e+09
C14: 서울 | D14: 양천 | E14: 서울특별시 양천구 목동 122-2 | F14: 24067200000 | G14: 216216170 | H14: 24283416170 | I14: 0.495 | J14: 1.2020291e+10 | K14: 1388000000 | L14: 23700000000 | N14: 23700000000 | O14: 2025.04.02 | Q14: 계약해제
B15: Pipeline 합계 | Q15: =Q13

Sheet 입찰공고(261014)
B1: ■ KLI 보유 주유소 매각 입찰공고 반영 (공고일 2026.10.14)
B2: 출처: (주)코람코라이프인프라위탁관리부동산투자회사 「입찰 공고문 — 보유 자산 매각」(2026.10.14). 금액·면적은 2026(예정) 시트 값을 수식으로 참조함.
B4: 1. 매각 개요
B5: 매도자 | C5: (주)코람코라이프인프라위탁관리부동산투자회사
B6: 매각 방식 | C6: 경쟁입찰(매수의향서 LOI 제출), 개별 매각 19개 자산. 유찰 시 수의계약 전환 가능
B7: 예상 일정 | C7: 입찰공고 2026.10.14(수) → 입찰마감 2026.11.19(목) → 우선협상대상자 선정 2026.11월 중 → 매매계약 체결 2026.12월 말 → 소유권이전 2027.01월 이후 (매도자 사정에 따라 변경 가능)
B8: LOI 제출 | C8: 방문: 2026.11.19(목) 13:00~16:00, 코람코자산신탁 본사 8층 회의실 / 우편: 2026.11.19(목) 18:00 이전 도착분
B9: LOI 기재사항 | C9: 입찰참여자 정보, 희망 매수금액(건물분 VAT 별도), 자금조달계획(증빙), 매입 후 사용계획, 기타 매매조건·지급방법·일정
B10: 입찰보증금 | C10: 건당 1억원(100,000,000원), 하나은행 183-910051-83204(예금주 KLI). 이행(입찰)보증보험(보증기간 최소 10개월)으로 대체 가능. 미납 시 LOI 무효, 우협 선정 후 계약 미체결·해제 시 미반환
B11: 계약금 등 | C11: 매매계약 시 매매금액의 10% 계약금. MOU 체결 시 매매금액의 5% 이행보증금(우협 입찰보증금은 이행보증금에 충당)
B12: 특약 | C12: 매매계약 체결과 동시에 임차인 에이치디현대오일뱅크㈜와 「토양오염검사 및 그 후속조치에 관한 합의서」 체결. 토지거래허가구역 소재 자산은 허가 후 계약
B13: 매각주관사 | C13: 세빌스코리아(신규원 차장 010-7231-8291), (주)부동산플래닛(김재희 이사 010-5500-8779), 쿠시먼앤드웨이크필드코리아(정예원 차장 010-8695-6466) — CA·개인정보동의서는 3개사 중 택1 제출
B15: 2. 입찰공고 대상 자산 (19개) ↔ 2026(예정) 시트 대조
B16: 공고 No. | C16: 공고 자산명 | D16: 시트 주유소명 | E16: 시트 NO | F16: 지역 | G16: 공고 상세주소(지번) | H16: 공고 대지면적(㎡) | I16: 공고 대지면적(평) | J16: 시트 대지면적(㎡) | K16: 면적 차이 (㎡) | L16: 보증금 | M16: 장부가(계) | N16: 감정평가(담보) | O16: 상환비율 | P16: 회수 원본
B17: 1 | C17: 공단1 | D17: 공단1 | E17: ='2026(예정)'!B5 | F17: ='2026(예정)'!E5 | G17: 인천광역시 남동구 남촌동 624 | H17: 3302 | I17: 999 | J17: ='2026(예정)'!H5 | K17: =J17-H17 | L17: ='2026(예정)'!L5 | M17: ='2026(예정)'!U5 | N17: ='2026(예정)'!Y5 | O17: ='2026(예정)'!Z5 | P17: ='2026(예정)'!AA5
B18: 2 | C18: 공단2 | D18: 공단2 | E18: ='2026(예정)'!B6 | F18: ='2026(예정)'!E6 | G18: 인천광역시 남동구 고잔동 673-10 | H18: 3636 | I18: 1100 | J18: ='2026(예정)'!H6 | K18: =J18-H18 | L18: ='2026(예정)'!L6 | M18: ='2026(예정)'!U6 | N18: ='2026(예정)'!Y6 | O18: ='2026(예정)'!Z6 | P18: ='2026(예정)'!AA6
B19: 3 | C19: 부평공단 | D19: 부평공단셀프 | E19: ='2026(예정)'!B21 | F19: ='2026(예정)'!E21 | G19: 인천광역시 부평구 갈산동 181-8 | H19: 1827 | I19: 553 | J19: ='2026(예정)'!H21 | K19: =J19-H19 | L19: ='2026(예정)'!L21 | M19: ='2026(예정)'!U21 | N19: ='2026(예정)'!Y21 | O19: ='2026(예정)'!Z21 | P19: ='2026(예정)'!AA21
B20: 4 | C20: 산곡셀프 | D20: 산곡셀프 | E20: ='2026(예정)'!B9 | F20: ='2026(예정)'!E9 | G20: 인천광역시 부평구 산곡동 411-16 | H20: 1292 | I20: 391 | J20: ='2026(예정)'!H9 | K20: =J20-H20 | L20: ='2026(예정)'!L9 | M20: ='2026(예정)'!U9 | N20: ='2026(예정)'!Y9 | O20: ='2026(예정)'!Z9 | P20: ='2026(예정)'!AA9
B21: 5 | C21: 둔전셀프 | D21: 둔전셀프 | E21: ='2026(예정)'!B20 | F21: ='2026(예정)'!E20 | G21: 경기도 용인시 처인구 둔전리 52-1, 11, 15, 18, 19 | H21: 1304 | I21: 394 | J21: ='2026(예정)'!H20 | K21: =J21-H21 | L21: ='2026(예정)'!L20 | M21: ='2026(예정)'!U20 | N21: ='2026(예정)'!Y20 | O21: ='2026(예정)'!Z20 | P21: ='2026(예정)'!AA20
B22: 6 | C22: 프리미엄셀프 | D22: 프리미엄셀프 | E22: ='2026(예정)'!B7 | F22: ='2026(예정)'!E7 | G22: 경기도 화성시 동탄구 석우동 3-6 | H22: 1676 | I22: 507 | J22: ='2026(예정)'!H7 | K22: =J22-H22 | L22: ='2026(예정)'!L7 | M22: ='2026(예정)'!U7 | N22: ='2026(예정)'!Y7 | O22: ='2026(예정)'!Z7 | P22: ='2026(예정)'!AA7
B23: 7 | C23: 송탄제일 | D23: 송탄제일셀프 | E23: ='2026(예정)'!B8 | F23: ='2026(예정)'!E8 | G23: 경기도 평택시 장당동 477-2, 4, 6 | H23: 1173 | I23: 355 | J23: ='2026(예정)'!H8 | K23: =J23-H23 | L23: ='2026(예정)'!L8 | M23: ='2026(예정)'!U8 | N23: ='2026(예정)'!Y8 | O23: ='2026(예정)'!Z8 | P23: ='2026(예정)'!AA8
B24: 8 | C24: 새광주 | D24: 새광주셀프 | E24: ='2026(예정)'!B18 | F24: ='2026(예정)'!E18 | G24: 경기도 광주시 쌍령동 113-8 | H24: 1442 | I24: 436 | J24: ='2026(예정)'!H18 | K24: =J24-H24 | L24: ='2026(예정)'!L18 | M24: ='2026(예정)'!U18 | N24: ='2026(예정)'!Y18 | O24: ='2026(예정)'!Z18 | P24: ='2026(예정)'!AA18
B25: 9 | C25: 노은 | D25: 노은 | E25: ='2026(예정)'!B26 | F25: ='2026(예정)'!E26 | G25: 대전광역시 유성구 노은동 534-11, 12 | H25: 1323 | I25: 400 | J25: ='2026(예정)'!H26 | K25: =J25-H25 | L25: ='2026(예정)'!L26 | M25: ='2026(예정)'!U26 | N25: ='2026(예정)'!Y26 | O25: ='2026(예정)'!Z26 | P25: ='2026(예정)'!AA26
B26: 10 | C26: 제천대로 | D26: 제천대로셀프 | E26: ='2026(예정)'!B19 | F26: ='2026(예정)'!E19 | G26: 충청북도 제천시 청전동 125-12 | H26: 1383 | I26: 418 | J26: ='2026(예정)'!H19 | K26: =J26-H26 | L26: ='2026(예정)'!L19 | M26: ='2026(예정)'!U19 | N26: ='2026(예정)'!Y19 | O26: ='2026(예정)'!Z19 | P26: ='2026(예정)'!AA19
B27: 11 | C27: 조양 | D27: 조양 | E27: ='2026(예정)'!B13 | F27: ='2026(예정)'!E13 | G27: 충청북도 제천시 천남동 30-3, 4, 5, 9, 16, 9-12 | H27: 4886 | I27: 1478 | J27: ='2026(예정)'!H13 | K27: =J27-H27 | L27: ='2026(예정)'!L13 | M27: ='2026(예정)'!U13 | N27: ='2026(예정)'!Y13 | O27: ='2026(예정)'!Z13 | P27: ='2026(예정)'!AA13
B28: 12 | C28: 교대셀프 | D28: 교대셀프 | E28: ='2026(예정)'!B23 | F28: ='2026(예정)'!E23 | G28: 충청북도 청주시 분평동 246-3, 33 | H28: 3164 | I28: 957 | J28: ='2026(예정)'!H23 | K28: =J28-H28 | L28: ='2026(예정)'!L23 | M28: ='2026(예정)'!U23 | N28: ='2026(예정)'!Y23 | O28: ='2026(예정)'!Z23 | P28: ='2026(예정)'!AA23
B29: 13 | C29: 남대구IC | D29: 남대구IC셀프 | E29: ='2026(예정)'!B24 | F29: ='2026(예정)'!E24 | G29: 대구광역시 달서구 월성동 210, 210-6 | H29: 2216 | I29: 670 | J29: ='2026(예정)'!H24 | K29: =J29-H29 | L29: ='2026(예정)'!L24 | M29: ='2026(예정)'!U24 | N29: ='2026(예정)'!Y24 | O29: ='2026(예정)'!Z24 | P29: ='2026(예정)'!AA24
B30: 14 | C30: 경대셀프 | D30: 경대셀프 | E30: ='2026(예정)'!B22 | F30: ='2026(예정)'!E22 | G30: 대구광역시 북구 침산동 13-49, 50, 109, 117 | H30: 1460 | I30: 442 | J30: ='2026(예정)'!H22 | K30: =J30-H30 | L30: ='2026(예정)'!L22 | M30: ='2026(예정)'!U22 | N30: ='2026(예정)'!Y22 | O30: ='2026(예정)'!Z22 | P30: ='2026(예정)'!AA22
B31: 15 | C31: 새화랑 | D31: 새화랑 | E31: ='2026(예정)'!B25 | F31: ='2026(예정)'!E25 | G31: 경상북도 경주시 동천동 936 | H31: 2391 | I31: 723 | J31: ='2026(예정)'!H25 | K31: =J31-H31 | L31: ='2026(예정)'!L25 | M31: ='2026(예정)'!U25 | N31: ='2026(예정)'!Y25 | O31: ='2026(예정)'!Z25 | P31: ='2026(예정)'!AA25
B32: 16 | C32: 열린 | D32: 열린 | E32: ='2026(예정)'!B28 | F32: ='2026(예정)'!E28 | G32: 경상북도 포항시 남구 연일읍 생지리 379-1, 5, 6, 8 | H32: 2141 | I32: 648 | J32: ='2026(예정)'!H28 | K32: =J32-H32 | L32: ='2026(예정)'!L28 | M32: ='2026(예정)'!U28 | N32: ='2026(예정)'!Y28 | O32: ='2026(예정)'!Z28 | P32: ='2026(예정)'!AA28
B33: 17 | C33: 양산대로 | D33: 양산대로 | E33: ='2026(예정)'!B11 | F33: ='2026(예정)'!E11 | G33: 경상남도 양산시 상북면 소토리 563 | H33: 1850 | I33: 560 | J33: ='2026(예정)'!H11 | K33: =J33-H33 | L33: ='2026(예정)'!L11 | M33: ='2026(예정)'!U11 | N33: ='2026(예정)'!Y11 | O33: ='2026(예정)'!Z11 | P33: ='2026(예정)'!AA11
B34: 18 | C34: 극동셀프 | D34: 극동셀프 | E34: ='2026(예정)'!B12 | F34: ='2026(예정)'!E12 | G34: 경상남도 창원시 마산회원구 석전동 270-32 | H34: 2082 | I34: 630 | J34: ='2026(예정)'!H12 | K34: =J34-H34 | L34: ='2026(예정)'!L12 | M34: ='2026(예정)'!U12 | N34: ='2026(예정)'!Y12 | O34: ='2026(예정)'!Z12 | P34: ='2026(예정)'!AA12
B35: 19 | C35: 밀양현대 | D35: 밀양현대 | E35: ='2026(예정)'!B27 | F35: ='2026(예정)'!E27 | G35: 경상남도 밀양시 삼문동 358-110 | H35: 1497 | I35: 453 | J35: ='2026(예정)'!H27 | K35: =J35-H35 | L35: ='2026(예정)'!L27 | M35: ='2026(예정)'!U27 | N35: ='2026(예정)'!Y27 | O35: ='2026(예정)'!Z27 | P35: ='2026(예정)'!AA27
B36: 합계 (19개) | H36: =SUM(H17:H35) | I36: =SUM(I17:I35) | J36: =SUM(J17:J35) | K36: =SUM(K17:K35) | L36: =SUM(L17:L35) | M36: =SUM(M17:M35) | N36: =SUM(N17:N35) | P36: =SUM(P17:P35)
B38: 3. 2026(예정) '신규' 중 이번 공고에 미포함된 자산
B39: 시트 NO | C39: 지역 | D39: 시트 주유소명 | E39: 상세주소 | L39: 보증금 | M39: 장부가(계) | N39: 감정평가(담보) | P39: 회수 원본
B40: ='2026(예정)'!B10 | C40: ='2026(예정)'!E10 | D40: ='2026(예정)'!F10 | E40: ='2026(예정)'!G10 | L40: ='2026(예정)'!L10 | M40: ='2026(예정)'!U10 | N40: ='2026(예정)'!Y10 | P40: ='2026(예정)'!AA10
B41: ='2026(예정)'!B14 | C41: ='2026(예정)'!E14 | D41: ='2026(예정)'!F14 | E41: ='2026(예정)'!G14 | L41: ='2026(예정)'!L14 | M41: ='2026(예정)'!U14 | N41: ='2026(예정)'!Y14 | P41: ='2026(예정)'!AA14
B42: ='2026(예정)'!B15 | C42: ='2026(예정)'!E15 | D42: ='2026(예정)'!F15 | E42: ='2026(예정)'!G15 | L42: ='2026(예정)'!L15 | M42: ='2026(예정)'!U15 | N42: ='2026(예정)'!Y15 | P42: ='2026(예정)'!AA15
B43: ='2026(예정)'!B16 | C43: ='2026(예정)'!E16 | D43: ='2026(예정)'!F16 | E43: ='2026(예정)'!G16 | L43: ='2026(예정)'!L16 | M43: ='2026(예정)'!U16 | N43: ='2026(예정)'!Y16 | P43: ='2026(예정)'!AA16
...

Sheet 매입장부가
E1: 1 | F1: 2 | G1: 3 | H1: 4 | I1: 5 | J1: 6 | K1: 7 | L1: 8 | M1: 9 | N1: 10 | O1: 11 | P1: 12 | Q1: 13 | R1: 14 | S1: 15 | T1: 16 | U1: 17 | V1: 18 | W1: 19 | X1: 20
B2: NO | C2: SSM | D2: 구 Name (SKN 운영) | E2: 신 Name (HDO 운영) | F2: 운영/개발 | G2: 지역 | H2: 주소 | K2: 부동산 장부가액 안분 | T2: 매매대금 배분
K3: 토지 | M3: 건물 | O3: 구축물 | R3: 매입장부가 | X3: 매입가
K4: 토지가액 | L4: 비율 | M4: 건물가액 | N4: 비율 | O4: 구축물가액 | P4: 비율 | Q4: 건물등 소계 | R4: 합계 | T4: 토지 | U4: 건물 | V4: 구축물 등 | W4: 건물등 소계 | X4: 합계
B5: 1 | C5: 10427 | D5: 고속 | E5: 고속셀프 | F5: 운영 | G5: 서울 | H5: 서울 강동구 둔촌동 600-1, 600 | K5: =$K$192*L5 | L5: 0.012811405 | M5: =$M$192*N5 | N5: 0.0049249836 | O5: =$O$192*P5 | P5: 0.0071922627 | Q5: =M5+O5 | R5: =K5+Q5 | T5: 11243000000 | U5: 224000000 | V5: 276000000 | W5: =SUM(U5:V5) | X5: =SUM(T5,W5)
B6: 2 | C6: 15067 | D6: 명일 | E6: 명일셀프 | F6: 운영 | G6: 서울 | H6: 서울 강동구 명일동 305-51 | K6: =$K$192*L6 | L6: 0.0088465592 | M6: =$M$192*N6 | N6: 0.012522096 | O6: =$O$192*P6 | P6: 0.0014491585 | Q6: =M6+O6 | R6: =K6+Q6 | T6: 7763000000 | U6: 569000000 | V6: 56000000 | W6: =SUM(U6:V6) | X6: =SUM(T6,W6)
B7: 3 | C7: 10092 | D7: 해바라기(서울강서) | E7: 강서제일셀프 | F7: 운영 | G7: 서울 | H7: 서울 강서구 화곡동 983-1 | K7: =$K$192*L7 | L7: 0.0080599084 | M7: =$M$192*N7 | N7: 0.0033685713 | O7: =$O$192*P7 | P7: 0.0022718534 | Q7: =M7+O7 | R7: =K7+Q7 | T7: 7073000000 | U7: 153000000 | V7: 87000000 | W7: =SUM(U7:V7) | X7: =SUM(T7,W7)
B8: 4 | C8: 10096 | D8: 장호 | E8: 장호셀프 | F8: 운영 | G8: 서울 | H8: 서울 광진구 자양동 677-5 | K8: =$K$192*L8 | L8: 0.017364676 | M8: =$M$192*N8 | N8: 0.0066633753 | O8: =$O$192*P8 | P8: 0.0032128849 | Q8: =M8+O8 | R8: =K8+Q8 | T8: 15239000000 | U8: 303000000 | V8: 123000000 | W8: =SUM(U8:V8) | X8: =SUM(T8,W8)
B9: 5 | C9: 10016 | D9: 대명 | E9: 대명셀프 | F9: 운영 | G9: 서울 | H9: 서울 광진구 화양동 302-13 | K9: =$K$192*L9 | L9: 0.013887227 | M9: =$M$192*N9 | N9: 0.0060072483 | O9: =$O$192*P9 | P9: 0.0044279517 | Q9: =M9+O9 | R9: =K9+Q9 | T9: 12187000000 | U9: 273000000 | V9: 170000000 | W9: =SUM(U9:V9) | X9: =SUM(T9,W9)
B10: 6 | C10: 15762 | D10: 순환도로 | E10: 금천제일 | F10: 운영 | G10: 서울 | H10: 서울 금천구 독산동 900-4 | K10: =$K$192*L10 | L10: 0.0048311719 | M10: =$M$192*N10 | N10: 0.0036768963 | O10: =$O$192*P10 | P10: 0.0053938007 | Q10: =M10+O10 | R10: =K10+Q10 | T10: 4240000000 | U10: 167000000 | V10: 207000000 | W10: =SUM(U10:V10) | X10: =SUM(T10,W10)
B11: 7 | C11: 10425 | D11: 하계 | E11: 하계 | F11: 운영 | G11: 서울 | H11: 서울 노원구 하계동 243-3 | K11: =$K$192*L11 | L11: 0.0066164383 | M11: =$M$192*N11 | N11: 0.0020568795 | O11: =$O$192*P11 | P11: 0.0026415136 | Q11: =M11+O11 | R11: =K11+Q11 | T11: 5806000000 | U11: 93000000 | V11: 101000000 | W11: =SUM(U11:V11) | X11: =SUM(T11,W11)
B12: 8 | C12: 10062 | D12: 흑석동 | E12: 흑석동셀프 | F12: 운영 | G12: 서울 | H12: 서울 동작구 흑석동 9-46 | K12: =$K$192*L12 | L12: 0.010598528 | M12: =$M$192*N12 | N12: 0.0014343136 | O12: =$O$192*P12 | P12: 0.0022333589 | Q12: =M12+O12 | R12: =K12+Q12 | T12: 9301000000 | U12: 65000000 | V12: 86000000 | W12: =SUM(U12:V12) | X12: =SUM(T12,W12)
B13: 9 | C13: 32489 | D13: Happy Auto | E13: 마포제일 | F13: 운영 | G13: 서울 | H13: 서울 마포구 창전동 13-6 | K13: =$K$192*L13 | L13: 0.019590719 | M13: =$M$192*N13 | N13: 0.035969768 | O13: =$O$192*P13 | P13: 0.015504216 | Q13: =M13+O13 | R13: =K13+Q13 | T13: 17192000000 | U13: =1634000000+1500000000 | V13: 595000000 | W13: =SUM(U13:V13) | X13: =SUM(T13,W13)
B14: 10 | C14: 10023 | D14: 아리랑 | E14: 아리랑 | F14: 운영 | G14: 서울 | H14: 서울 성북구 정릉동 113-61 | K14: =$K$192*L14 | L14: 0.0092553797 | M14: =$M$192*N14 | N14: 0.002864229 | O14: =$O$192*P14 | P14: 0.0056464377 | Q14: =M14+O14 | R14: =K14+Q14 | T14: 8122000000 | U14: 130000000 | V14: 217000000 | W14: =SUM(U14:V14) | X14: =SUM(T14,W14)
B15: 11 | C15: 25678 | D15: 북악 | E15: 북악셀프 | F15: 운영 | G15: 서울 | H15: 서울 성북구 정릉동 428 | K15: =$K$192*L15 | L15: 0.0052570062 | M15: =$M$192*N15 | N15: 0.013089958 | O15: =$O$192*P15 | P15: 0.0028589621 | Q15: =M15+O15 | R15: =K15+Q15 | T15: 4613000000 | U15: 595000000 | V15: 110000000 | W15: =SUM(U15:V15) | X15: =SUM(T15,W15)
B16: 12 | C16: 17838 | D16: 서원 | E16: 서원 | F16: 운영 | G16: 서울 | H16: 서울 송파구 가락동 146-6 | K16: =$K$192*L16 | L16: 0.011241277 | M16: =$M$192*N16 | N16: 0.0038029701 | O16: =$O$192*P16 | P16: 0.0012297627 | Q16: =M16+O16 | R16: =K16+Q16 | T16: 9865000000 | U16: 173000000 | V16: 47000000 | W16: =SUM(U16:V16) | X16: =SUM(T16,W16)
B17: 13 | C17: 10420 | D17: 올림픽 | E17: 올림픽셀프 | F17: 운영 | G17: 서울 | H17: 서울 송파구 오금동 4 | K17: =$K$192*L17 | L17: 0.019686302 | M17: =$M$192*N17 | N17: 0.0057616228 | O17: =$O$192*P17 | P17: 0.009578105 | Q17: =M17+O17 | R17: =K17+Q17 | T17: 17276000000 | U17: 262000000 | V17: 367000000 | W17: =SUM(U17:V17) | X17: =SUM(T17,W17)
B18: 14 | C18: 25380 | D18: SKOK(서울양천) | E18: 양천 | F18: 운영 | G18: 서울 | H18: 서울 양천구 목동 122-2 | K18: =$K$192*L18 | L18: 0.01558543 | M18: =$M$192*N18 | N18: 0.0072090664 | O18: =$O$192*P18 | P18: 0.012693735 | Q18: =M18+O18 | R18: =K18+Q18 | T18: 13677000000 | U18: 328000000 | V18: 487000000 | W18: =SUM(U18:V18) | X18: =SUM(T18,W18)
B19: 15 | C19: 10068 | D19: 남부(신월) | E19: 남부순환셀프 | F19: 운영 | G19: 서울 | H19: 서울 양천구 신월동 525-1 | K19: =$K$192*L19 | L19: 0.016015921 | M19: =$M$192*N19 | N19: 0.011356924 | O19: =$O$192*P19 | P19: 0.0026280405 | Q19: =M19+O19 | R19: =K19+Q19 | T19: 14055000000 | U19: 516000000 | V19: 101000000 | W19: =SUM(U19:V19) | X19: =SUM(T19,W19)
B20: 16 | C20: 22792 | D20: 윈윈 | E20: 영등포제일셀프 | F20: 운영 | G20: 서울 | H20: 서울 영등포구 대림동 667-9 | K20: =$K$192*L20 | L20: 0.006093738 | M20: =$M$192*N20 | N20: 0.0042252843 | O20: =$O$192*P20 | P20: 0.0070642119 | Q20: =M20+O20 | R20: =K20+Q20 | T20: 5348000000 | U20: 192000000 | V20: 271000000 | W20: =SUM(U20:V20) | X20: =SUM(T20,W20)
B21: 17 | C21: 10051 | D21: 강변(용산) | E21: 강변현대 | F21: 운영 | G21: 서울 | H21: 서울 용산구 청암동 168-22 | K21: =$K$192*L21 | L21: 0.0093414023 | M21: =$M$192*N21 | N21: 0.0014730196 | O21: =$O$192*P21 | P21: 0.0020693498 | Q21: =M21+O21 | R21: =K21+Q21 | T21: 8198000000 | U21: 67000000 | V21: 79000000 | W21: =SUM(U21:V21) | X21: =SUM(T21,W21)
B22: 18 | C22: 10050 | D22: SK흥국 | E22: 한남동 | F22: 운영 | G22: 서울 | H22: 서울 용산구 한남동 726-370 | K22: =$K$192*L22 | L22: 0.010411956 | M22: =$M$192*N22 | N22: 0.0036467686 | O22: =$O$192*P22 | P22: 0.0027372222 | Q22: =M22+O22 | R22: =K22+Q22 | T22: 9137000000 | U22: 166000000 | V22: 105000000 | W22: =SUM(U22:V22) | X22: =SUM(T22,W22)
B23: 19 | C23: 10411 | D23: 재동 | E23: 재동 | F23: 운영 | G23: 서울 | H23: 서울 종로구 경운동 96-18 | K23: =$K$192*L23 | L23: 0.015782541 | M23: =$M$192*N23 | N23: 0.0013034998 | O23: =$O$192*P23 | P23: 0.0026810271 | Q23: =M23+O23 | R23: =K23+Q23 | T23: 13850000000 | U23: 59000000 | V23: 103000000 | W23: =SUM(U23:V23) | X23: =SUM(T23,W23)
B24: 20 | C24: 10028 | D24: 독립문 | E24: 독립문 | F24: 운영 | G24: 서울 | H24: 서울 서대문구 홍제동 103-9 | K24: =$K$192*L24 | L24: 0.009230932 | M24: =$M$192*N24 | N24: 0.0018988464 | O24: =$O$192*P24 | P24: 0.0012955656 | Q24: =M24+O24 | R24: =K24+Q24 | T24: 8101000000 | U24: 86000000 | V24: 50000000 | W24: =SUM(U24:V24) | X24: =SUM(T24,W24)
B25: 21 | C25: 23404 | D25: 삼일 | E25: 능곡역 | F25: 운영 | G25: 경기 | H25: 경기 고양시 덕양구 토당동 866-3 | K25: =$K$192*L25 | L25: 0.0043599075 | M25: =$M$192*N25 | N25: 0.003832777 | O25: =$O$192*P25 | P25: 0.0029153452 | Q25: =M25+O25 | R25: =K25+Q25 | T25: 3826000000 | U25: 174000000 | V25: 112000000 | W25: =SUM(U25:V25) | X25: =SUM(T25,W25)
... B79: 75 | C79: 11030 | D79: 경기 | E79: 송탄제일셀프 | F79: 운영 | G79: 경기 | H79: 경기 평택시 장당동 477-2 | K79: =$K$192*L79 | L79: 0.0032478622 | M79: =$M$192*N79 | N79: 0.0038938538 | O79: =$O$192*P79 | P79: 0.0023487518 | Q79: =M79+O79 | R79: =K79+Q79 | T79: 2850000000 | U79: 177000000 | V79: 90000000 | W79: =SUM(U79:V79) | X79: =SUM(T79,W79)
B80: 76 | C80: 32379 | D80: 포천대로 | E80: 포천대로셀프 | F80: 운영 | G80: 경기 | H80: 경기 포천시 소흘읍 이동교리 338-30,338-32 | K80: =$K$192*L80 | L80: 0.0025906877 | M80: =$M$192*N80 | N80: 0.0036650288 | O80: =$O$192*P80 | P80: 0.002103157 | Q80: =M80+O80 | R80: =K80+Q80 | T80: 2273000000 | U80: 167000000 | V80: 81000000 | W80: =SUM(U80:V80) | X80: =SUM(T80,W80) | Y80: =#REF!/10^8
B81: 77 | C81: 32446 | D81: 삼성(반월리) | E81: 동탄제일 | F81: 운영 | G81: 경기 | H81: 경기 화성시 반월동 539-1 | K81: =$K$192*L81 | L81: 0.0032539143 | M81: =$M$192*N81 | N81: 0.0028645326 | O81: =$O$192*P81 | P81: 0.011846471 | Q81: =M81+O81 | R81: =K81+Q81 | T81: 2849000000 | U81: 130000000 | V81: 454000000 | W81: =SUM(U81:V81) | X81: =SUM(T81,W81)
B82: 78 | C82: 26236 | D82: 봉담톨게이트 | E82: 봉담IC셀프 | F82: 운영 | G82: 경기 | H82: 경기 화성군 봉담읍 동화리 357-1, 357-3 | K82: =$K$192*L82 | L82: 0.0042271645 | M82: =$M$192*N82 | N82: 0.0034879933 | O82: =$O$192*P82 | P82: 0.0027221482 | Q82: =M82+O82 | R82: =K82+Q82 | T82: 3710000000 | U82: 158000000 | V82: 104000000 | W82: =SUM(U82:V82) | X82: =SUM(T82,W82)
B83: 79 | C83: 34138 | D83: SK프리미엄 | E83: 프리미엄셀프 | F83: 운영 | G83: 경기 | H83: 경기 화성시 석우동 3-6 | K83: =$K$192*L83 | L83: 0.0075827138 | M83: =$M$192*N83 | N83: 0.0093258075 | O83: =$O$192*P83 | P83: 0.0026624138 | Q83: =M83+O83 | R83: =K83+Q83 | T83: 6654000000 | U83: 424000000 | V83: 102000000 | W83: =SUM(U83:V83) | X83: =SUM(T83,W83)
B84: 80 | C84: 11210 | D84: 우영 | E84: 효행로셀프 | F84: 운영 | G84: 경기 | H84: 경기 화성시 안녕동 39-1, 39-4, 39-5 | K84: =$K$192*L84 | L84: 0.00087273182 | M84: =$M$192*N84 | N84: 0.0017283116 | O84: =$O$192*P84 | P84: 0.0026376415 | Q84: =M84+O84 | R84: =K84+Q84 | T84: 766000000 | U84: 79000000 | V84: 101000000 | W84: =SUM(U84:V84) | X84: =SUM(T84,W84)
B85: 81 | C85: 15410 | D85: 21세기(경기화성) | E85: 향남현대 | F85: 운영 | G85: 경기 | H85: 경기 화성군 향남면 제암리 286-4, 286-10 | K85: =$K$192*L85 | L85: 0.0028910342 | M85: =$M$192*N85 | N85: 0.0014073879 | O85: =$O$192*P85 | P85: 0.0024386704 | Q85: =M85+O85 | R85: =K85+Q85 | T85: 2537000000 | U85: 64000000 | V85: 94000000 | W85: =SUM(U85:V85) | X85: =SUM(T85,W85)
B86: 82 | C86: 10786 | D86: 유화(인천) | E86: 유화셀프 | F86: 운영 | G86: 인천 | H86: 인천 계양구 효성동 206-9 | K86: =$K$192*L86 | L86: 0.0051304965 | M86: =$M$192*N86 | N86: 0.0035594839 | O86: =$O$192*P86 | P86: 0.012526623 | Q86: =M86+O86 | R86: =K86+Q86 | T86: 4502000000 | U86: 162000000 | V86: 481000000 | W86: =SUM(U86:V86) | X86: =SUM(T86,W86)
B87: 83 | C87: 10780 | D87: SK인천 | E87: 인천셀프 | F87: 운영 | G87: 인천 | H87: 인천 남구 도화동 53-1 | K87: =$K$192*L87 | L87: 0.0038081195 | M87: =$M$192*N87 | N87: 0.007602748 | O87: =$O$192*P87 | P87: 0.0045755214 | Q87: =M87+O87 | R87: =K87+Q87 | T87: 3342000000 | U87: 345000000 | V87: 176000000 | W87: =SUM(U87:V87) | X87: =SUM(T87,W87)
B88: 84 | C88: 10796 | D88: 장미(인천남주) | E88: 미추홀셀프 | F88: 운영 | G88: 인천 | H88: 인천 남구 주안동 1468 | K88: =$K$192*L88 | L88: 0.0043416739 | M88: =$M$192*N88 | N88: 0.0021469059 | O88: =$O$192*P88 | P88: 0.0045087221 | Q88: =M88+O88 | R88: =K88+Q88 | T88: 3810000000 | U88: 98000000 | V88: 173000000 | W88: =SUM(U88:V88) | X88: =SUM(T88,W88)
B89: 85 | C89: 20054 | D89: 공단2 | E89: 공단2 | F89: 운영 | G89: 인천 | H89: 인천 남동구 고잔동 673-10 | K89: =$K$192*L89 | L89: 0.0089612794 | M89: =$M$192*N89 | N89: 0.01401472 | O89: =$O$192*P89 | P89: 0.0061447374 | Q89: =M89+O89 | R89: =K89+Q89 | T89: 7864000000 | U89: 637000000 | V89: 236000000 | W89: =SUM(U89:V89) | X89: =SUM(T89,W89)
B90: 86 | C90: 10848 | D90: 공단1 | E90: 공단1 | F90: 운영 | G90: 인천 | H90: 인천 남동구 남촌동 624 | K90: =$K$192*L90 | L90: 0.0073545375 | M90: =$M$192*N90 | N90: 0.0076149636 | O90: =$O$192*P90 | P90: 0.004341792 | Q90: =M90+O90 | R90: =K90+Q90 | T90: 6454000000 | U90: 346000000 | V90: 167000000 | W90: =SUM(U90:V90) | X90: =SUM(T90,W90)
B91: 87 | C91: 10782 | D91: 인천HW | E91: 만수동셀프 | F91: 운영 | G91: 인천 | H91: 인천 남동구 만수동 884-6 | K91: =$K$192*L91 | L91: 0.010147297 | M91: =$M$192*N91 | N91: 0.010793584 | O91: =$O$192*P91 | P91: 0.014009499 | Q91: =M91+O91 | R91: =K91+Q91 | T91: 8905000000 | U91: 490000000 | V91: 537000000 | W91: =SUM(U91:V91) | X91: =SUM(T91,W91)
B92: 88 | C92: 10797 | D92: 공단(인천부평) | E92: 부평공단셀프 | F92: 운영 | G92: 인천 | H92: 인천 부평구 갈산동 181-8 | K92: =$K$192*L92 | L92: 0.0067815454 | M92: =$M$192*N92 | N92: 0.0040137666 | O92: =$O$192*P92 | P92: 0.0054783074 | Q92: =M92+O92 | R92: =K92+Q92 | T92: 5951000000 | U92: 182000000 | V92: 210000000 | W92: =SUM(U92:V92) | X92: =SUM(T92,W92)
... B99: 95 | C99: 34566 | D99: 영종행복 | E99: 영종셀프 | F99: 운영 | G99: 인천 | H99: 인천 중구 자연대로 55 | K99: =$K$192*L99 | L99: 0.0056499886 | M99: =$M$192*N99 | N99: 0.01223087 | O99: =$O$192*P99 | P99: 0.0034590684 | Q99: =M99+O99 | R99: =K99+Q99 | T99: 4958000000 | U99: 556000000 | V99: 133000000 | W99: =SUM(U99:V99) | X99: =SUM(T99,W99)
...

Sheet 상환비율
A2: 부록 7
A3: 대출금의 지역별 상환 비율
A5: 1 | C5: Tranche A 대출금
A7: 지역 | B7: 지역 | C7: 담보가액 | D7: 최종 상환비율 | E7: 상환 대상액
A8: 서울특별시 | B8: 서울 | C8: 252005592870 | D8: 0.495 | E8: 124749000000
A9: 경기도 | B9: 경기 | C9: 344123749000 | D9: 0.495 | E9: 170368000000
A10: 인천광역시 | B10: 인천 | C10: 114219899770 | D10: 0.495 | E10: 56546000000
A11: 광주광역시 | B11: 광주 | C11: 22364057570 | D11: 0.44 | E11: 9843000000
A12: 대전광역시 | B12: 대전 | C12: 51999174950 | D12: 0.44 | E12: 22885000000
A13: 부산광역시 | B13: 부산 | C13: 78307139580 | D13: 0.44 | E13: 34459000000
A14: 대구광역시 | B14: 대구 | C14: 50610358410 | D14: 0.44 | E14: 22272000000
A15: 울산광역시 | B15: 울산 | C15: 9739606000 | D15: 0.44 | E15: 4286000000
A16: 전라남도 | B16: 전남 | C16: 1779828650 | D16: 0.385 | E16: 686000000
A17: 강원도 | B17: 강원 | C17: 15102149090 | D17: 0.385 | E17: 5817000000
A18: 충청북도 | B18: 충북 | C18: 26069964120 | D18: 0.385 | E18: 10041000000
A19: 충청남도 | B19: 충남 | C19: 20341056470 | D19: 0.385 | E19: 7834000000
... A22: 경상남도 | B22: 경남 | C22: 42951015660 | D22: 0.385 | E22: 16542000000
A23: 기타 | B23: 기타 | C23: 6459660710 | E23: 23295000000
A24: 합 계 | C24: 1078073691830 | E24: 525800000000
A25: 단, 경수대로,제이셀프,아산셀프,동래(이하 총칭하여 “기타자산”)에 대해서는 본 지역별 상환비율이 아닌 하기 2.기타자산 상환대상액을 적용한다.
A29: 2 | C29: 기타자산 상환대상액(세부내역)
A31: 지역 | C31: 매입가 | D31: 상환비율(매입가 대비) | E31: 상환 대상액
A32: 경수대로 | B32: 기타 | C32: 13461000000 | D32: 0.668 | E32: 8991000000
A33: 제이셀프 | B33: 기타 | C33: 4755000000 | D33: 0.668 | E33: 3176000000
A34: 아산셀프 | B34: 기타 | C34: 7205000000 | D34: 0.668 | E34: 4813000000
A35: 동래 | B35: 기타 | C35: 9456000000 | D35: 0.668 | E35: 6315000000
A36: 합계 | C36: 34877000000 | E36: 23295000000

Sheet 담보대출상환비율
B2: ■ 지역별 상환비율
B3: 지역 | D3: 담보가액 | E3: 상환대상액 | F3: 최종 상환비율
B4: 서울특별시 | C4: 서울 | D4: 252005592870 | E4: 124749000000 | F4: 0.495
B5: 경기도 | C5: 경기 | D5: 344123749000 | E5: 170368000000 | F5: 0.495
B6: 인천광역시 | C6: 인천 | D6: 114219899770 | E6: 56546000000 | F6: 0.495
B7: 광주광역시 | C7: 광주 | D7: 22364057570 | E7: 9843000000 | F7: 0.44
B8: 대전광역시 | C8: 대전 | D8: 51999174950 | E8: 22885000000 | F8: 0.44
B9: 부산광역시 | C9: 부산 | D9: 78307139580 | E9: 34459000000 | F9: 0.44
B10: 대구광역시 | C10: 대구 | D10: 50610358410 | E10: 22272000000 | F10: 0.44
B11: 울산광역시 | C11: 울산 | D11: 9739606000 | E11: 4286000000 | F11: 0.44
B12: 전라남도 | C12: 전남 | D12: 1779828650 | E12: 686000000 | F12: 0.385
B13: 강원도 | C13: 강원 | D13: 15102149090 | E13: 5817000000 | F13: 0.385
B14: 충청북도 | C14: 충북 | D14: 26069964120 | E14: 10041000000 | F14: 0.385
B15: 충청남도 | C15: 충남 | D15: 20341056470 | E15: 7834000000 | F15: 0.385
... B18: 경상남도 | C18: 경남 | D18: 42951015660 | E18: 16542000000 | F18: 0.385
B19: 경수대로 | C19: 기타 | D19: 6459660710 | E19: 8991000000
B20: 제이셀프 | C20: 기타 | E20: 3176000000
B21: 아산셀프 | C21: 기타 | E21: 4813000000
B22: 동래 | C22: 기타 | E22: 6315000000
B23: 합 계 | C23: - | D23: =SUM(D4:D22) | E23: =SUM(E4:E22)

Sheet 주유소별가격(담보)
B1: 감정평가 총괄표
C2: 1 | D2: 2 | E2: 3 | F2: 4 | G2: 5 | H2: 답모가액
B3: 주유소 번호 | C3: 주유소명 | D3: 소재지 | E3: 토지 금액(원) | F3: 건물 금액(원) | G3: 기계기구 (유류저장시설)(원) | H3: 감정평가액(원) | I3: 비 고
B4: 1 | C4: 고속셀프 | D4: 서울특별시 강동구 둔촌동 600-1 | E4: 20491000000 | F4: 237832080 | G4: 감정평가 외 | H4: 20728832080 | I4: - | L4: =MID(B4,17,3)
B5: 2 | C5: 강서제일셀프 | D5: 서울특별시 강서구 화곡동 20-1 외 | E5: 16504768000 | F5: 102188990 | G5: 감정평가 외 | H5: 16606956990 | I5: - | L5: =MID(B5,17,3)
B6: 3 | C6: 장호셀프 | D6: 서울특별시 광진구 자양동 677-5 | E6: 26178360000 | F6: 403170510 | G6: 감정평가 외 | H6: 26581530510 | I6: - | L6: =MID(B6,17,3)
B7: 4 | C7: 대명셀프 | D7: 서울특별시 광진구 화양동 302-13 | E7: 20004600000 | F7: 283695800 | G7: 감정평가 외 | H7: 20288295800 | I7: - | L7: =MID(B7,17,3)
B8: 5 | C8: 금천제일 | D8: 서울특별시 금천구 독산동 900-4 | E8: 8.14215e+09 | F8: 179183880 | G8: 감정평가 외 | H8: 8.3213339e+09 | I8: - | L8: =MID(B8,17,3)
B9: 6 | C9: 하계 | D9: 서울특별시 노원구 하계동 243-3 | E9: 7073360000 | F9: 76577120 | G9: 감정평가 외 | H9: 7149937120 | I9: - | L9: =MID(B9,17,3)
B10: 7 | C10: 흑석동셀프 | D10: 서울특별시 동작구 흑석동 9-46 | E10: 15846000000 | F10: 70025800 | G10: 감정평가 외 | H10: 15916025800 | I10: - | L10: =MID(B10,17,3)
B11: 8 | C11: 아리랑 | D11: 서울특별시 성북구 정릉동 113-61 | E11: 11135000000 | F11: 131408760 | G11: 감정평가 외 | H11: 11266408760 | I11: - | L11: =MID(B11,17,3)
B12: 9 | C12: 북악셀프 | D12: 서울특별시 성북구 정릉동 428 | E12: 8860950000 | F12: 764490830 | G12: 감정평가 외 | H12: 9625440830 | I12: - | L12: =MID(B12,17,3)
B13: 10 | C13: 올림픽셀프 | D13: 서울특별시 송파구 오금동 4 외 | E13: 34351240000 | F13: 271752070 | G13: 감정평가 외 | H13: 34622992070 | I13: - | L13: =MID(B13,17,3)
B14: 11 | C14: 양천 | D14: 서울특별시 양천구 목동 122-2 외 | E14: 24067200000 | F14: 216216170 | G14: 감정평가 외 | H14: 24283416170 | I14: - | L14: =MID(B14,17,3)
B15: 12 | C15: 남부순환셀프 | D15: 서울특별시 양천구 신월동 525-1 | E15: 23555880000 | F15: 468050890 | G15: 감정평가 외 | H15: 24023930890 | I15: - | L15: =MID(B15,17,3)
... B37: 35 | C37: 신도시셀프 | D37: 경기도 안산시 상록구 월피동 445-5 | E37: 6584865000 | F37: 996000360 | G37: 감정평가 외 | H37: 7580865360 | I37: - | L37: =MID(B37,17,3)
B38: 36 | C38: 제이셀프 | D38: 경기도 안산시 선부동 1076-16 | E38: - | F38: - | G38: - | H38: - | I38: 타인점유사용 | L38: =MID(B38,17,3)
B39: 37 | C39: 동양 | D39: 경기도 안산시 단원구 신길동 1743 | E39: 3340590000 | F39: 25493000 | G39: 감정평가 외 | H39: 3366083000 | I39: - | L39: =MID(B39,17,3)
B40: 39 | C40: 반월셀프 | D40: 경기도 안산시 일동 648 외 | E40: 3646812000 | F40: 24631390 | G40: 감정평가 외 | H40: 3671443390 | I40: - | L40: =MID(B40,17,3)
B41: 40 | C41: 팔곡셀프 | D41: 경기도 안산시 팔곡이동 445-4 | E41: 3741700000 | F41: 98104160 | G41: 감정평가 외 | H41: 3839804160 | I41: - | L41: =MID(B41,17,3)
B42: 41 | C42: 안성TG | D42: 경기도 안성시 공도면 진사리 2-6 외 | E42: 5148960000 | F42: 161997080 | G42: 감정평가 외 | H42: 5310957080 | I42: - | L42: =MID(B42,17,3)
B43: 42 | C43: 관양현대셀프 | D43: 경기도 안양시 동안구 관양동 1466-3 외 | E43: 8724396000 | F43: 297608040 | G43: 감정평가 외 | H43: 9022004040 | I43: - | L43: =MID(B43,17,3)
B44: 43 | C44: 비산현대셀프 | D44: 경기도 안양시 동안구 비산동 576-13 | E44: 35789656000 | F44: 1778170830 | G44: 감정평가 외 | H44: 37567826830 | I44: - | L44: =MID(B44,17,3)
B45: 44 | C45: 호계현대셀프 | D45: 경기도 안양시 동안구 호계동 1006-7 | E45: 5542400000 | F45: 346785010 | G45: 감정평가 외 | H45: 5889185010 | I45: - | L45: =MID(B45,17,3)
B46: 45 | C46: 석수현대셀프 | D46: 경기도 안양시 만안구 석수동 259-1 | E46: 13103838000 | F46: 510273460 | G46: 감정평가 외 | H46: 13614111460 | I46: - | L46: =MID(B46,17,3)
B47: 46 | C47: 드림셀프 | D47: 경기도 양주시 광사동 659-3 | E47: 3019112000 | F47: 123303600 | G47: 감정평가 외 | H47: 3142415600 | I47: - | L47: =MID(B47,17,3)
B48: 47 | C48: 오산셀프 | D48: 경기도 오산시 원동 513 | E48: 3023820000 | F48: 220067160 | G48: 감정평가 외 | H48: 3243887160 | I48: - | L48: =MID(B48,17,3)
B49: 48 | C49: 동백스카이셀프 | D49: 경기도 용인시 기흥구 상하동 639-1 | E49: 13578930000 | F49: 493740300 | G49: 감정평가 외 | H49: 14072670300 | I49: - | L49: =MID(B49,17,3)
B50: 49 | C50: 기흥현대셀프 | D50: 경기도 용인시 기흥구 구갈동 270-1 | E50: 3591864000 | F50: 107891350 | G50: 감정평가 외 | H50: 3699755350 | I50: - | L50: =MID(B50,17,3)
... B115: 114 | C115: 산북 | D115: 전북특별자치도 군산시 산북동 1055 외 | E115: 1712870000 | F115: 174526520 | G115: 감정평가 외 | H115: 1887396520 | I115: - | L115: =MID(B115,17,3)
B116: 115 | C116: 이리 | D116: 전북특별자치도 익산시 팔봉동 848-1 외 | E116: 1262031700 | F116: 268927780 | G116: 감정평가 외 | H116: 1530959480 | I116: -
B117: 116 | C117: 하남제일 | D117: 광주광역시 광산구 도천동 295-19 외 | E117: 6487880000 | F117: 235995840 | G117: 감정평가 외 | H117: 6723875840 | I117: -
B118: 117 | C118: 장덕셀프 | D118: 광주광역시 광산구 장덕동 85-3 | E118: 2027810000 | F118: 127343310 | G118: 감정평가 외 | H118: 2155153310 | I118: -
B119: 118 | C119: 동천마을셀프 | D119: 광주광역시 북구 동림동 885-12 | E119: 5127506000 | F119: 151830000 | G119: 감정평가 외 | H119: 5279336000 | I119: -
B120: 119 | C120: 양산 | D120: 광주광역시 북구 양산동 610-17 | E120: 2641320000 | F120: 46143350 | G120: 감정평가 외 | H120: 2687463350 | I120: -
B121: 120 | C121: 빛고을로셀프 | D121: 광주광역시 북구 용두동 1043-1 외 | E121: 1559520000 | F121: 123891370 | G121: 감정평가 외 | H121: 1683411370 | I121: -
B122: 121 | C122: 베스트현대셀프 | D122: 광주광역시 서구 치평동 203-5 외 | E122: 3650920000 | F122: 183897700 | G122: 감정평가 외 | H122: 3834817700 | I122: -
B123: 122 | C123: 고현셀프 | D123: 경상남도 거제시 신현읍 고현리 963-4 | E123: 5466610000 | F123: 213472320 | G123: 감정평가 외 | H123: 5680082320 | I123: -
B124: 123 | C124: 조선해양 | D124: 경상남도 거제시 아주동 246-7 | E124: 2660100000 | F124: 237064440 | G124: 감정평가 외 | H124: 2897164440 | I124: -
B125: 124 | C125: 김해대로셀프 | D125: 경상남도 김해시 삼계동 1492-1 | E125: 2295038000 | F125: 126849600 | G125: 감정평가 외 | H125: 2421887600 | I125: -
...
