Workbook

Sheet 0.통합리스트
A1: 필수입력 | B1: 기표일(2026-10-29) 이체 통합 리스트 — 1.Equity인수수수료 · 2.대출관련수수료 · 3.담보신탁보수 · 4.이자유보금예치 취합
A2: 순번 | B2: 항목 | C2: 계정 | D2: 금액 | E2: 과세유형 | F2: 출금처 | G2: 출금은행 | H2: 출금계좌 | I2: 입금처 | J2: 입금은행 | K2: 입금계좌 | L2: 부가세(10%) | M2: 실제 이체금액 | N2: 지급기한 | O2: 구분
A3: 1 | B3: ='1.Equity인수수수료'!B3 | C3: =IF('1.Equity인수수수료'!C3="","",'1.Equity인수수수료'!C3) | D3: ='1.Equity인수수수료'!D3 | E3: ='1.Equity인수수수료'!E3 | F3: ='1.Equity인수수수료'!F3 | G3: ='1.Equity인수수수료'!G3 | H3: ='1.Equity인수수수료'!H3 | I3: ='1.Equity인수수수료'!I3 | J3: ='1.Equity인수수수료'!J3 | K3: ='1.Equity인수수수료'!K3 | ... N3: ='1.Equity인수수수료'!N3 | O3: Equity 인수수수료
A4: 2 | B4: ='1.Equity인수수수료'!B4 | C4: =IF('1.Equity인수수수료'!C4="","",'1.Equity인수수수료'!C4) | D4: ='1.Equity인수수수료'!D4 | E4: ='1.Equity인수수수료'!E4 | F4: ='1.Equity인수수수료'!F4 | G4: ='1.Equity인수수수료'!G4 | H4: ='1.Equity인수수수료'!H4 | I4: ='1.Equity인수수수료'!I4 | J4: ='1.Equity인수수수료'!J4 | K4: ='1.Equity인수수수료'!K4 | ... N4: ='1.Equity인수수수료'!N4 | O4: Equity 인수수수료
A5: 3 | B5: ='1.Equity인수수수료'!B5 | C5: =IF('1.Equity인수수수료'!C5="","",'1.Equity인수수수료'!C5) | D5: ='1.Equity인수수수료'!D5 | E5: ='1.Equity인수수수료'!E5 | F5: ='1.Equity인수수수료'!F5 | G5: ='1.Equity인수수수료'!G5 | H5: ='1.Equity인수수수료'!H5 | I5: ='1.Equity인수수수료'!I5 | J5: ='1.Equity인수수수료'!J5 | K5: ='1.Equity인수수수료'!K5 | ... N5: ='1.Equity인수수수료'!N5 | O5: Equity 인수수수료
A6: 4 | B6: ='2.대출관련수수료'!B3 | C6: =IF('2.대출관련수수료'!C3="","",'2.대출관련수수료'!C3) | D6: ='2.대출관련수수료'!D3 | E6: ='2.대출관련수수료'!E3 | F6: ='2.대출관련수수료'!F3 | G6: ='2.대출관련수수료'!G3 | H6: ='2.대출관련수수료'!H3 | I6: ='2.대출관련수수료'!I3 | J6: ='2.대출관련수수료'!J3 | K6: ='2.대출관련수수료'!K3 | ... N6: ='2.대출관련수수료'!N3 | O6: 대출관련수수료
A7: 5 | B7: ='2.대출관련수수료'!B4 | C7: =IF('2.대출관련수수료'!C4="","",'2.대출관련수수료'!C4) | D7: ='2.대출관련수수료'!D4 | E7: ='2.대출관련수수료'!E4 | F7: ='2.대출관련수수료'!F4 | G7: ='2.대출관련수수료'!G4 | H7: ='2.대출관련수수료'!H4 | I7: ='2.대출관련수수료'!I4 | J7: ='2.대출관련수수료'!J4 | K7: ='2.대출관련수수료'!K4 | ... N7: ='2.대출관련수수료'!N4 | O7: 대출관련수수료
A8: 6 | B8: ='2.대출관련수수료'!B5 | C8: =IF('2.대출관련수수료'!C5="","",'2.대출관련수수료'!C5) | D8: ='2.대출관련수수료'!D5 | E8: ='2.대출관련수수료'!E5 | F8: ='2.대출관련수수료'!F5 | G8: ='2.대출관련수수료'!G5 | H8: ='2.대출관련수수료'!H5 | I8: ='2.대출관련수수료'!I5 | J8: ='2.대출관련수수료'!J5 | K8: ='2.대출관련수수료'!K5 | ... N8: ='2.대출관련수수료'!N5 | O8: 대출관련수수료
A9: 7 | B9: ='2.대출관련수수료'!B6 | C9: =IF('2.대출관련수수료'!C6="","",'2.대출관련수수료'!C6) | D9: ='2.대출관련수수료'!D6 | E9: ='2.대출관련수수료'!E6 | F9: ='2.대출관련수수료'!F6 | G9: ='2.대출관련수수료'!G6 | H9: ='2.대출관련수수료'!H6 | I9: ='2.대출관련수수료'!I6 | J9: ='2.대출관련수수료'!J6 | K9: ='2.대출관련수수료'!K6 | ... N9: ='2.대출관련수수료'!N6 | O9: 대출관련수수료
A10: 8 | B10: ='2.대출관련수수료'!B7 | C10: =IF('2.대출관련수수료'!C7="","",'2.대출관련수수료'!C7) | D10: ='2.대출관련수수료'!D7 | E10: ='2.대출관련수수료'!E7 | F10: ='2.대출관련수수료'!F7 | G10: ='2.대출관련수수료'!G7 | H10: ='2.대출관련수수료'!H7 | I10: ='2.대출관련수수료'!I7 | J10: ='2.대출관련수수료'!J7 | K10: ='2.대출관련수수료'!K7 | ... N10: ='2.대출관련수수료'!N7 | O10: 대출관련수수료
A11: 9 | B11: ='2.대출관련수수료'!B8 | C11: =IF('2.대출관련수수료'!C8="","",'2.대출관련수수료'!C8) | D11: ='2.대출관련수수료'!D8 | E11: ='2.대출관련수수료'!E8 | F11: ='2.대출관련수수료'!F8 | G11: ='2.대출관련수수료'!G8 | H11: ='2.대출관련수수료'!H8 | I11: ='2.대출관련수수료'!I8 | J11: ='2.대출관련수수료'!J8 | K11: ='2.대출관련수수료'!K8 | ... N11: ='2.대출관련수수료'!N8 | O11: 대출관련수수료
A12: 10 | B12: ='2.대출관련수수료'!B9 | C12: =IF('2.대출관련수수료'!C9="","",'2.대출관련수수료'!C9) | D12: ='2.대출관련수수료'!D9 | E12: ='2.대출관련수수료'!E9 | F12: ='2.대출관련수수료'!F9 | G12: ='2.대출관련수수료'!G9 | H12: ='2.대출관련수수료'!H9 | I12: ='2.대출관련수수료'!I9 | J12: ='2.대출관련수수료'!J9 | K12: ='2.대출관련수수료'!K9 | ... N12: ='2.대출관련수수료'!N9 | O12: 대출관련수수료
A13: 11 | B13: ='2.대출관련수수료'!B10 | C13: =IF('2.대출관련수수료'!C10="","",'2.대출관련수수료'!C10) | D13: ='2.대출관련수수료'!D10 | E13: ='2.대출관련수수료'!E10 | F13: ='2.대출관련수수료'!F10 | G13: ='2.대출관련수수료'!G10 | H13: ='2.대출관련수수료'!H10 | I13: ='2.대출관련수수료'!I10 | J13: ='2.대출관련수수료'!J10 | K13: ='2.대출관련수수료'!K10 | ... N13: ='2.대출관련수수료'!N10 | O13: 대출관련수수료
A14: 12 | B14: ='2.대출관련수수료'!B11 | C14: =IF('2.대출관련수수료'!C11="","",'2.대출관련수수료'!C11) | D14: ='2.대출관련수수료'!D11 | E14: ='2.대출관련수수료'!E11 | F14: ='2.대출관련수수료'!F11 | G14: ='2.대출관련수수료'!G11 | H14: ='2.대출관련수수료'!H11 | I14: ='2.대출관련수수료'!I11 | J14: ='2.대출관련수수료'!J11 | K14: ='2.대출관련수수료'!K11 | ... N14: ='2.대출관련수수료'!N11 | O14: 대출관련수수료
A15: 13 | B15: ='2.대출관련수수료'!B12 | C15: =IF('2.대출관련수수료'!C12="","",'2.대출관련수수료'!C12) | D15: ='2.대출관련수수료'!D12 | E15: ='2.대출관련수수료'!E12 | F15: ='2.대출관련수수료'!F12 | G15: ='2.대출관련수수료'!G12 | H15: ='2.대출관련수수료'!H12 | I15: ='2.대출관련수수료'!I12 | J15: ='2.대출관련수수료'!J12 | K15: ='2.대출관련수수료'!K12 | ... N15: ='2.대출관련수수료'!N12 | O15: 대출관련수수료
A16: 14 | B16: ='2.대출관련수수료'!B13 | C16: =IF('2.대출관련수수료'!C13="","",'2.대출관련수수료'!C13) | D16: ='2.대출관련수수료'!D13 | E16: ='2.대출관련수수료'!E13 | F16: ='2.대출관련수수료'!F13 | G16: ='2.대출관련수수료'!G13 | H16: ='2.대출관련수수료'!H13 | I16: ='2.대출관련수수료'!I13 | J16: ='2.대출관련수수료'!J13 | K16: ='2.대출관련수수료'!K13 | ... N16: ='2.대출관련수수료'!N13 | O16: 대출관련수수료
A17: 15 | B17: ='2.대출관련수수료'!B14 | C17: =IF('2.대출관련수수료'!C14="","",'2.대출관련수수료'!C14) | D17: ='2.대출관련수수료'!D14 | E17: ='2.대출관련수수료'!E14 | F17: ='2.대출관련수수료'!F14 | G17: ='2.대출관련수수료'!G14 | H17: ='2.대출관련수수료'!H14 | I17: ='2.대출관련수수료'!I14 | J17: ='2.대출관련수수료'!J14 | K17: ='2.대출관련수수료'!K14 | ... N17: ='2.대출관련수수료'!N14 | O17: 대출관련수수료
... A31: 29 | B31: ='2.대출관련수수료'!B28 | C31: =IF('2.대출관련수수료'!C28="","",'2.대출관련수수료'!C28) | D31: ='2.대출관련수수료'!D28 | E31: ='2.대출관련수수료'!E28 | F31: ='2.대출관련수수료'!F28 | G31: ='2.대출관련수수료'!G28 | H31: ='2.대출관련수수료'!H28 | I31: ='2.대출관련수수료'!I28 | J31: ='2.대출관련수수료'!J28 | K31: ='2.대출관련수수료'!K28 | ... N31: ='2.대출관련수수료'!N28 | O31: 대출관련수수료
A32: 30 | B32: ='3.담보신탁보수'!B3 | C32: =IF('3.담보신탁보수'!C3="","",'3.담보신탁보수'!C3) | D32: ='3.담보신탁보수'!D3 | E32: ='3.담보신탁보수'!E3 | F32: ='3.담보신탁보수'!F3 | G32: ='3.담보신탁보수'!G3 | H32: ='3.담보신탁보수'!H3 | I32: ='3.담보신탁보수'!I3 | J32: ='3.담보신탁보수'!J3 | K32: ='3.담보신탁보수'!K3 | ... N32: ='3.담보신탁보수'!N3 | O32: 담보신탁보수
A33: 31 | B33: ='4.이자유보금예치'!B3 | C33: =IF('4.이자유보금예치'!C3="","",'4.이자유보금예치'!C3) | D33: ='4.이자유보금예치'!D3 | E33: ='4.이자유보금예치'!E3 | F33: ='4.이자유보금예치'!F3 | G33: ='4.이자유보금예치'!G3 | H33: ='4.이자유보금예치'!H3 | I33: ='4.이자유보금예치'!I3 | J33: ='4.이자유보금예치'!J3 | K33: ='4.이자유보금예치'!K3 | ... N33: ='4.이자유보금예치'!N3 | O33: 이자유보금 예치
A34: 32 | B34: ='4.이자유보금예치'!B4 | C34: =IF('4.이자유보금예치'!C4="","",'4.이자유보금예치'!C4) | D34: ='4.이자유보금예치'!D4 | E34: ='4.이자유보금예치'!E4 | F34: ='4.이자유보금예치'!F4 | G34: ='4.이자유보금예치'!G4 | H34: ='4.이자유보금예치'!H4 | I34: ='4.이자유보금예치'!I4 | J34: ='4.이자유보금예치'!J4 | K34: ='4.이자유보금예치'!K4 | ... N34: ='4.이자유보금예치'!N4 | O34: 이자유보금 예치
A35: 33 | B35: ='4.이자유보금예치'!B5 | C35: =IF('4.이자유보금예치'!C5="","",'4.이자유보금예치'!C5) | D35: ='4.이자유보금예치'!D5 | E35: ='4.이자유보금예치'!E5 | F35: ='4.이자유보금예치'!F5 | G35: ='4.이자유보금예치'!G5 | H35: ='4.이자유보금예치'!H5 | I35: ='4.이자유보금예치'!I5 | J35: ='4.이자유보금예치'!J5 | K35: ='4.이자유보금예치'!K5 | ... N35: ='4.이자유보금예치'!N5 | O35: 이자유보금 예치
B36: 합계 | D36: =SUM(D3:D35) | L36: =SUM(L3:L35) | M36: =SUM(M3:M35)
B37: └ Equity 인수수수료 | D37: =SUMIF($O$3:$O$35,"Equity 인수수수료",D$3:D$35) | L37: =SUMIF($O$3:$O$35,"Equity 인수수수료",L$3:L$35) | M37: =SUMIF($O$3:$O$35,"Equity 인수수수료",M$3:M$35)
B38: └ 대출관련수수료 | D38: =SUMIF($O$3:$O$35,"대출관련수수료",D$3:D$35) | L38: =SUMIF($O$3:$O$35,"대출관련수수료",L$3:L$35) | M38: =SUMIF($O$3:$O$35,"대출관련수수료",M$3:M$35)
B39: └ 담보신탁보수 | D39: =SUMIF($O$3:$O$35,"담보신탁보수",D$3:D$35) | L39: =SUMIF($O$3:$O$35,"담보신탁보수",L$3:L$35) | M39: =SUMIF($O$3:$O$35,"담보신탁보수",M$3:M$35)
B40: └ 이자유보금 예치 | D40: =SUMIF($O$3:$O$35,"이자유보금 예치",D$3:D$35) | L40: =SUMIF($O$3:$O$35,"이자유보금 예치",L$3:L$35) | M40: =SUMIF($O$3:$O$35,"이자유보금 예치",M$3:M$35)
A42: · 1~4탭 데이터 행을 수식으로 가져옵니다. 금액·계좌는 각 탭에서 고치면 여기도 바뀝니다.
A43: · '금액'은 공급가액, '실제 이체금액'은 과세 건 부가세 10% 포함 금액입니다. 삼성증권 인수수수료는 면세(비과세) 기준입니다.
A44: · 근거(약정서 조항·통장사본)는 각 탭 O열을 참고하세요.

Sheet 요약
A1: 기표일(2026-10-29) 수수료·보수·이자유보금 이체내역 요약
A3: 구분 | B3: 건수 | C3: 금액(공급가액) | D3: 부가세 | E3: 실제 이체금액 | F3: 비고
A4: 1.Equity인수수수료 | B4: 3 | C4: ='1.Equity인수수수료'!D9 | D4: ='1.Equity인수수수료'!L9 | E4: ='1.Equity인수수수료'!M9 | F4: 우리투자증권·엠지캐피탈 과세(계약서 '부가가치세 별도'), 삼성증권 면세(비과세) 기준
A5: 2.대출관련수수료 | B5: 26 | C5: ='2.대출관련수수료'!D32 | D5: ='2.대출관련수수료'!L32 | E5: ='2.대출관련수수료'!M32 | F5: 25개 대주(우리은행 주선·참여 2건), 전부 부가가치세 없음
A6: 3.담보신탁보수 | B6: 1 | C6: ='3.담보신탁보수'!D7 | D6: ='3.담보신탁보수'!L7 | E6: ='3.담보신탁보수'!M7 | F6: 신탁재산 관리보수, 부가가치세 없음
A7: 4.이자유보금예치 | B7: 3 | C7: ='4.이자유보금예치'!D9 | D7: ='4.이자유보금예치'!L9 | E7: ='4.이자유보금예치'!M9 | F7: Tranche A(A-1+A-2)·B 이자유보계좌
A8: 합계 | B8: =SUM(B4:B7) | C8: =SUM(C4:C7) | D8: =SUM(D4:D7) | E8: =SUM(E4:E7)
A10: · 각 탭 A~K열은 운용역 제공 이체 양식(순번·항목·계정·금액·과세유형·출금처·출금은행·출금계좌·입금처·입금은행·입금계좌)과 같고, L~O열(부가세·실제 이체금액·지급기한·근거)은 확인용으로 덧붙였습니다.
A11: · '금액'은 양식 예시(인수수수료 36,000,000 과세)와 같이 공급가액 기준이며, 과세 건은 부가세 10%를 더한 '실제 이체금액'을 함께 표시합니다.
A12: · 출금처는 양식 기본값(운영계좌 우리은행 1005-804-963776)으로 채웠습니다. 계정 열은 비워 두었습니다.
A13: · 노란 칸은 확인이 필요한 항목입니다(신협중앙회 통장사본 미접수). 삼성증권 인수수수료는 면세(비과세) 기준으로 반영했습니다.
A14: · '0.통합리스트' 탭은 1~4탭 데이터 행을 수식으로 그대로 가져오므로, 각 탭을 고치면 자동 반영됩니다(탭에 행을 추가하면 통합리스트에도 행 추가 필요).
A15: · 수익 확약이 아닌 이체 준비용 집계표이며, 금액·계좌는 체결본 약정서와 통장사본을 기준으로 합니다.

Sheet 1.Equity인수수수료
A1: 필수입력 | B1: Equity 인수수수료 이체내역 (종류주식 인수계약 체결본 2026-10-26 기준)
A2: 순번 | B2: 항목 | C2: 계정 | D2: 금액 | E2: 과세유형 | F2: 출금처 | G2: 출금은행 | H2: 출금계좌 | I2: 입금처 | J2: 입금은행 | K2: 입금계좌 | L2: 부가세(10%) | M2: 실제 이체금액 | N2: 지급기한 | O2: 근거·비고
A3: 1 | B3: 인수수수료(제1종 종류주식, 주선 및 잔액인수) | D3: 480000000 | E3: 과세 | F3: 운영계좌 | G3: 우리은행 | H3: 1005-804-963776 | I3: 주식회사 우리투자증권 | J3: 우리은행 | K3: 1003-700-005935 | L3: =IF(E3="과세",ROUNDDOWN(D3*0.1,0),0) | M3: =D3+L3 | N3: 거래종결일로부터 1영업일 이내 | O3: 인수약정금 240억원 × 2% (부가가치세 별도). [채결본] 인수계약서(제1종 종류주식)_우리투자증권_20261026 제5조 제1항 / 계좌: 주식회사 우리투자증권_우리은행 계좌 사본
A4: 2 | B4: 인수수수료(제1종 종류주식) | D4: 36000000 | E4: 과세 | F4: 운영계좌 | G4: 우리은행 | H4: 1005-804-963776 | I4: 엠지캐피탈(주) | J4: 우리은행 | K4: 894-000383-01-015 | L4: =IF(E4="과세",ROUNDDOWN(D4*0.1,0),0) | M4: =D4+L4 | N4: 거래종결일로부터 5영업일 이내 | O4: 인수약정금 30억원 × 1.2% (부가가치세 별도). [채결본] 인수계약서(제1종 종류주식)_엠지캐피탈_20261026 제5조 / 계좌: [엠지캐피탈] 우리은행 모계좌 (계약서 기재 계좌와 동일)
A5: 3 | B5: 인수수수료(삼성증권, 제2종 종류주식 주선 및 잔액인수) | D5: 1200000000 | E5: 비과세 | F5: 운영계좌 | G5: 우리은행 | H5: 1005-804-963776 | I5: 삼성증권(주) | J5: 우리은행 | K5: 061-219568-03-103 | L5: =IF(E5="과세",ROUNDDOWN(D5*0.1,0),0) | M5: =D5+L5 | N5: 거래종결일로부터 5영업일 이내 | O5: 인수약정금 500억원 × 2.4%. [채결본] 주선 및 인수계약서_삼성증권_20261026 제5조(부가가치세 문구 없음). 면세 기준: 증권사의 주선(투자중개업)·잔액인수(투자매매업) 용역 → 금융용역 면세(부가가치세법 제26조 제1항 제11호, 시행령 제40조) [내부 검토, 삼성증권 계산서 발행 여부 확인] / 계좌: [삼성증권] 계좌사본_우리은행
A6: 4 | F6: 운영계좌 | G6: 우리은행 | H6: 1005-804-963776
A7: 5 | F7: 운영계좌 | G7: 우리은행 | H7: 1005-804-963776
A8: 6 | F8: 운영계좌 | G8: 우리은행 | H8: 1005-804-963776
B9: 합계 | D9: =SUM(D3:D8) | L9: =SUM(L3:L8) | M9: =SUM(M3:M8)

Sheet 2.대출관련수수료
A1: 필수입력 | B1: 대출관련수수료 이체내역 (수수료약정서 체결본 2026-10-27 기준, 25개 대주·26건)
A2: 순번 | B2: 항목 | C2: 계정 | D2: 금액 | E2: 과세유형 | F2: 출금처 | G2: 출금은행 | H2: 출금계좌 | I2: 입금처 | J2: 입금은행 | K2: 입금계좌 | L2: 부가세(10%) | M2: 실제 이체금액 | N2: 지급기한 | O2: 근거·비고
A3: 1 | B3: 대출참여수수료(Tr.A-1 롯데캐피탈) | D3: 540000000 | E3: 비과세 | F3: 운영계좌 | G3: 우리은행 | H3: 1005-804-963776 | I3: 롯데캐피탈(주) | J3: 우리은행 | K3: 364-032300-03-001 | L3: =IF(E3="과세",ROUNDDOWN(D3*0.1,0),0) | M3: =D3+L3 | N3: 인출일(2026-10-29) | O3: 부가가치세 없음. 300억 × 1.8%. [체결본] 대출참여수수료약정서(Tr_A-1_롯데캐피탈) 제2조 / 계좌: ■롯데캐피탈 입금계좌 사본
A4: 2 | B4: 대출참여수수료(Tr.A-1 우리카드) | D4: 120000000 | E4: 비과세 | F4: 운영계좌 | G4: 우리은행 | H4: 1005-804-963776 | I4: (주)우리카드 | J4: 우리은행 | K4: 1005-504-287838 | L4: =IF(E4="과세",ROUNDDOWN(D4*0.1,0),0) | M4: =D4+L4 | N4: 인출일(2026-10-29) | O4: 부가가치세 없음. 100억 × 1.2%. [체결본] 대출참여수수료약정서(Tr_A-1_우리카드) 제2조 / 계좌: [우리카드] 수수료 및 원리금 상환 통장표지
A5: 3 | B5: 대출참여수수료(Tr.A-1 신용협동조합중앙회) | D5: 1000000 | E5: 비과세 | F5: 운영계좌 | G5: 우리은행 | H5: 1005-804-963776 | I5: 신협중앙회 | J5: 농협은행 | K5: 081-01-168860 | L5: =IF(E5="과세",ROUNDDOWN(D5*0.1,0),0) | M5: =D5+L5 | N5: 인출일(2026-10-29) | O5: 부가가치세 없음. [체결본] 대출참여수수료약정서(Tr_A-1_신협대주단)_20261027 제2조 표(대출약정금의 1.0%) / 계좌: 대주 통지처(261023 vf) 기재 수취계좌 — 통장사본 미접수
A6: 4 | B6: 대출참여수수료(Tr.A-1 서로신협) | D6: 40000000 | E6: 비과세 | F6: 운영계좌 | G6: 우리은행 | H6: 1005-804-963776 | I6: 서로신용협동조합 | J6: 신협 | K6: 131-000-941666 | L6: =IF(E6="과세",ROUNDDOWN(D6*0.1,0),0) | M6: =D6+L6 | N6: 인출일(2026-10-29) | O6: 부가가치세 없음. [체결본] 대출참여수수료약정서(Tr_A-1_신협대주단)_20261027 제2조 표(대출약정금의 1.0%) / 계좌: 서로 사업자등록증,계좌
A7: 5 | B7: 대출참여수수료(Tr.A-1 수지신협) | D7: 28000000 | E7: 비과세 | F7: 운영계좌 | G7: 우리은행 | H7: 1005-804-963776 | I7: 수지신협 | J7: 신협 | K7: 131-014-493393 | L7: =IF(E7="과세",ROUNDDOWN(D7*0.1,0),0) | M7: =D7+L7 | N7: 인출일(2026-10-29) | O7: 부가가치세 없음. [체결본] 대출참여수수료약정서(Tr_A-1_신협대주단)_20261027 제2조 표(대출약정금의 1.0%) / 계좌: 수지 사업자등록증,계좌
A8: 6 | B8: 대출참여수수료(Tr.A-1 정선신협) | D8: 24000000 | E8: 비과세 | F8: 운영계좌 | G8: 우리은행 | H8: 1005-804-963776 | I8: 정선신용협동조합 | J8: 신협 | K8: 131-019-058167 | L8: =IF(E8="과세",ROUNDDOWN(D8*0.1,0),0) | M8: =D8+L8 | N8: 인출일(2026-10-29) | O8: 부가가치세 없음. [체결본] 대출참여수수료약정서(Tr_A-1_신협대주단)_20261027 제2조 표(대출약정금의 1.0%) / 계좌: 정선 사업자등록증,계좌
A9: 7 | B9: 대출참여수수료(Tr.A-1 연희신협) | D9: 14000000 | E9: 비과세 | F9: 운영계좌 | G9: 우리은행 | H9: 1005-804-963776 | I9: 연희신협 | J9: 신협 | K9: 131-000-189579 | L9: =IF(E9="과세",ROUNDDOWN(D9*0.1,0),0) | M9: =D9+L9 | N9: 인출일(2026-10-29) | O9: 부가가치세 없음. [체결본] 대출참여수수료약정서(Tr_A-1_신협대주단)_20261027 제2조 표(대출약정금의 1.0%) / 계좌: 연희 사업자등록증,계좌
A10: 8 | B10: 대출참여수수료(Tr.A-1 금모래신협) | D10: 18000000 | E10: 비과세 | F10: 운영계좌 | G10: 우리은행 | H10: 1005-804-963776 | I10: 금모래신협 | J10: 신협 | K10: 131-000-001170 | L10: =IF(E10="과세",ROUNDDOWN(D10*0.1,0),0) | M10: =D10+L10 | N10: 인출일(2026-10-29) | O10: 부가가치세 없음. [체결본] 대출참여수수료약정서(Tr_A-1_신협대주단)_20261027 제2조 표(대출약정금의 1.0%) / 계좌: 금모래 사업자등록증,계좌
A11: 9 | B11: 대출참여수수료(Tr.A-1 남인천신협) | D11: 10000000 | E11: 비과세 | F11: 운영계좌 | G11: 우리은행 | H11: 1005-804-963776 | I11: 남인천신협 | J11: 신협 | K11: 131-000-942952 | L11: =IF(E11="과세",ROUNDDOWN(D11*0.1,0),0) | M11: =D11+L11 | N11: 인출일(2026-10-29) | O11: 부가가치세 없음. [체결본] 대출참여수수료약정서(Tr_A-1_신협대주단)_20261027 제2조 표(대출약정금의 1.0%) / 계좌: 남인천 사업자등록증,계좌
A12: 10 | B12: 대출참여수수료(Tr.A-1 미호신협) | D12: 13000000 | E12: 비과세 | F12: 운영계좌 | G12: 우리은행 | H12: 1005-804-963776 | I12: 미호신협 | J12: 신협 | K12: 131-002-821894 | L12: =IF(E12="과세",ROUNDDOWN(D12*0.1,0),0) | M12: =D12+L12 | N12: 인출일(2026-10-29) | O12: 부가가치세 없음. [체결본] 대출참여수수료약정서(Tr_A-1_신협대주단)_20261027 제2조 표(대출약정금의 1.0%) / 계좌: 미호신협 사업자등록증,계좌
A13: 11 | B13: 대출참여수수료(Tr.A-1 대구대서신협) | D13: 13000000 | E13: 비과세 | F13: 운영계좌 | G13: 우리은행 | H13: 1005-804-963776 | I13: 대구대서신협 | J13: 신협 | K13: 131-005-005290 | L13: =IF(E13="과세",ROUNDDOWN(D13*0.1,0),0) | M13: =D13+L13 | N13: 인출일(2026-10-29) | O13: 부가가치세 없음. [체결본] 대출참여수수료약정서(Tr_A-1_신협대주단)_20261027 제2조 표(대출약정금의 1.0%) / 계좌: 대구대서 사업자등록증,계좌
A14: 12 | B14: 대출참여수수료(Tr.A-1 한빛신협) | D14: 17000000 | E14: 비과세 | F14: 운영계좌 | G14: 우리은행 | H14: 1005-804-963776 | I14: 한빛신용협동조합 | J14: 신협 | K14: 131-003-657209 | L14: =IF(E14="과세",ROUNDDOWN(D14*0.1,0),0) | M14: =D14+L14 | N14: 인출일(2026-10-29) | O14: 부가가치세 없음. [체결본] 대출참여수수료약정서(Tr_A-1_신협대주단)_20261027 제2조 표(대출약정금의 1.0%) / 계좌: 한빛 사업자등록증,계좌
... A28: 26 | B28: 대출참여수수료(Tr.B 디비저축은행) | D28: 80000000 | E28: 비과세 | F28: 운영계좌 | G28: 우리은행 | H28: 1005-804-963776 | I28: (주)디비저축은행 | J28: 국민은행 | K28: 006-01-0381-794 | L28: =IF(E28="과세",ROUNDDOWN(D28*0.1,0),0) | M28: =D28+L28 | N28: 인출일(2026-10-29) | O28: 부가가치세 없음. 80억 × 1.0%. [체결본] 대출참여수수료약정서(Tr_B_DB저축은행) 제2조 / 계좌: [DB저축은행]_국민은행 예치금계좌
A29: 27 | F29: 운영계좌 | G29: 우리은행 | H29: 1005-804-963776
A30: 28 | F30: 운영계좌 | G30: 우리은행 | H30: 1005-804-963776
A31: 29 | F31: 운영계좌 | G31: 우리은행 | H31: 1005-804-963776
B32: 합계 | D32: =SUM(D3:D31) | L32: =SUM(L3:L31) | M32: =SUM(M3:M31)

Sheet 3.담보신탁보수
A1: 필수입력 | B1: 담보신탁보수 이체내역 (수탁자: 우리은행)
A2: 순번 | B2: 항목 | C2: 계정 | D2: 금액 | E2: 과세유형 | F2: 출금처 | G2: 출금은행 | H2: 출금계좌 | I2: 입금처 | J2: 입금은행 | K2: 입금계좌 | L2: 부가세(10%) | M2: 실제 이체금액 | N2: 지급기한 | O2: 근거·비고
A3: 1 | B3: 담보신탁보수(신탁재산 관리보수) | D3: 50000000 | E3: 비과세 | F3: 운영계좌 | G3: 우리은행 | H3: 1005-804-963776 | I3: (주)우리은행 신탁부 | J3: 우리은행 | K3: 003-441153-01-001 | L3: =IF(E3="과세",ROUNDDOWN(D3*0.1,0),0) | M3: =D3+L3 | N3: 수익권증서 발급 시(일시 선납) | O3: 금 5천만원, 부가가치세 없음. 부동산담보신탁계약서(2026-10-20 v02.3) 제18조·별지3 / 계좌: □신탁보수입금계좌표제부_우리은행신탁부. ※ 신탁원부 변경등기 시 관리보수 150만원 별도(특약 제16조) — 이번 이체 대상 아님
A4: 2 | F4: 운영계좌 | G4: 우리은행 | H4: 1005-804-963776
A5: 3 | F5: 운영계좌 | G5: 우리은행 | H5: 1005-804-963776
A6: 4 | F6: 운영계좌 | G6: 우리은행 | H6: 1005-804-963776
B7: 합계 | D7: =SUM(D3:D6) | L7: =SUM(L3:L6) | M7: =SUM(M3:M6)

Sheet 4.이자유보금예치
A1: 필수입력 | B1: 이자유보계좌 이자적립금 예치 내역 (대출약정서 v.final, 인출일 당일 3개월분 이자)
A2: 순번 | B2: 항목 | C2: 계정 | D2: 금액 | E2: 과세유형 | F2: 출금처 | G2: 출금은행 | H2: 출금계좌 | I2: 입금처 | J2: 입금은행 | K2: 입금계좌 | L2: 부가세(10%) | M2: 실제 이체금액 | N2: 지급기한 | O2: 근거·비고
A3: 1 | B3: 이자적립금 예치(Tranche A-1, 3개월분) | D3: ='이자유보금_계산'!G45 | E3: 비과세 | F3: 운영계좌 | G3: 우리은행 | H3: 1005-804-963776 | I3: Tranche A 이자유보계좌(차주 명의) | J3: 우리은행 | K3: 1005-504-965088 | L3: =IF(E3="과세",ROUNDDOWN(D3*0.1,0),0) | M3: =D3+L3 | N3: 인출일 당일(2026-10-29) | O3: 연 5.00%, 2026-10-29~2027-01-29(92일). 계산: '이자유보금_계산' 탭 / 대출약정서상 대출금입금계좌(1005-504-949583)에서 직접 이체할 수 있음 — 출금계좌 확인
A4: 2 | B4: 이자적립금 예치(Tranche A-2, 3개월분) | D4: ='이자유보금_계산'!G46 | E4: 비과세 | F4: 운영계좌 | G4: 우리은행 | H4: 1005-804-963776 | I4: Tranche A 이자유보계좌(차주 명의) | J4: 우리은행 | K4: 1005-504-965088 | L4: =IF(E4="과세",ROUNDDOWN(D4*0.1,0),0) | M4: =D4+L4 | N4: 인출일 당일(2026-10-29) | O4: CD 3.27%(10/26 3.26%·10/27 3.27%·10/28 3.27% 평균, 셋째 자리 반올림) + 1.43% = 연 4.70%, 92일. 계산: '이자유보금_계산' 탭 / 대출약정서상 대출금입금계좌(1005-504-949583)에서 직접 이체할 수 있음 — 출금계좌 확인
A5: 3 | B5: 이자적립금 예치(Tranche B, 3개월분) | D5: ='이자유보금_계산'!G47 | E5: 비과세 | F5: 운영계좌 | G5: 우리은행 | H5: 1005-804-963776 | I5: Tranche B 이자유보계좌(차주 명의) | J5: 우리은행 | K5: 1005-504-970089 | L5: =IF(E5="과세",ROUNDDOWN(D5*0.1,0),0) | M5: =D5+L5 | N5: 인출일 당일(2026-10-29) | O5: 연 6.00%, 92일. 계산: '이자유보금_계산' 탭 / 대출약정서상 대출금입금계좌(1005-504-949583)에서 직접 이체할 수 있음 — 출금계좌 확인
A6: 4 | F6: 운영계좌 | G6: 우리은행 | H6: 1005-804-963776
A7: 5 | F7: 운영계좌 | G7: 우리은행 | H7: 1005-804-963776
A8: 6 | F8: 운영계좌 | G8: 우리은행 | H8: 1005-804-963776
B9: 합계 | D9: =SUM(D3:D8) | L9: =SUM(L3:L8) | M9: =SUM(M3:M8)

Sheet 이자유보금_계산
A1: 이자유보계좌 이자적립금(3개월분) 계산 — 인출일 2026-10-29
A2: 대출약정서(v.final): 차주는 인출일 당일 Tranche A·B 대출금의 각 3개월분 이자 상당액을 각 이자유보계좌에 적립. 이자 = 원금 × 연이율 × 일수 ÷ 365, 초일 산입·말일 불산입, 대주별 원 미만 절사.
A3: 항목 | B3: 값 | C3: 비고
A4: 인출일(최초 이자기간 시작일) | B4: 46324 | C4: 기준 일정
A5: 최초 이자지급일(3개월 응당일) | B5: 46416 | C5: 2027-01-29(금) 영업일 — 조정 없음
A6: 이자기간 일수 | B6: =B5-B4 | C6: 초일 산입·말일 불산입
A7: 연 일수 | B7: 365 | C7: 2026~2027년 평년
A8: CD금리 ① 2026-10-26(월) | B8: 0.0326 | C8: 운용역 제공
A9: CD금리 ② 2026-10-27(화) | B9: 0.0327 | C9: 운용역 제공
A10: CD금리 ③ 2026-10-28(수) | B10: 0.0327 | C10: 운용역 제공
A11: CD금리 3영업일 단순평균 | B11: =AVERAGE(B8:B10) | C11: 반올림 전
A12: A-2 기준금리 | B12: =ROUND(B11,4) | C12: 소수점 아래 셋째 자리에서 반올림(%) → 3.27%
A13: A-2 가산금리 | B13: 0.0143 | C13: 대출약정서 제5조
A14: Tranche A-1 금리(고정) | B14: 0.05 | C14: 대출약정서 제5조
A15: Tranche A-2 적용금리 | B15: =B12+B13 | C15: 기준금리 + 1.43%
A16: Tranche B 금리(고정) | B16: 0.06 | C16: 대출약정서 제5조
A19: 대주 | B19: Tranche | C19: 대출약정금 | D19: 적용금리 | E19: 일수 | F19: 연일수 | G19: 3개월분 이자(원 미만 절사) | H19: 입금 이자유보계좌
A20: 롯데캐피탈(주) | B20: A-1 | C20: 30000000000 | D20: =$B$14 | E20: =$B$6 | F20: =$B$7 | G20: =ROUNDDOWN(C20*D20*E20/F20,0) | H20: Tranche A 이자유보계좌 1005-504-965088
A21: (주)우리카드 | B21: A-1 | C21: 10000000000 | D21: =$B$14 | E21: =$B$6 | F21: =$B$7 | G21: =ROUNDDOWN(C21*D21*E21/F21,0) | H21: Tranche A 이자유보계좌 1005-504-965088
A22: 신용협동조합중앙회 | B22: A-1 | C22: 100000000 | D22: =$B$14 | E22: =$B$6 | F22: =$B$7 | G22: =ROUNDDOWN(C22*D22*E22/F22,0) | H22: Tranche A 이자유보계좌 1005-504-965088
A23: 서로신용협동조합 | B23: A-1 | C23: 4000000000 | D23: =$B$14 | E23: =$B$6 | F23: =$B$7 | G23: =ROUNDDOWN(C23*D23*E23/F23,0) | H23: Tranche A 이자유보계좌 1005-504-965088
A24: 수지신용협동조합 | B24: A-1 | C24: 2800000000 | D24: =$B$14 | E24: =$B$6 | F24: =$B$7 | G24: =ROUNDDOWN(C24*D24*E24/F24,0) | H24: Tranche A 이자유보계좌 1005-504-965088
A25: 정선신용협동조합 | B25: A-1 | C25: 2400000000 | D25: =$B$14 | E25: =$B$6 | F25: =$B$7 | G25: =ROUNDDOWN(C25*D25*E25/F25,0) | H25: Tranche A 이자유보계좌 1005-504-965088
A26: 연희신용협동조합 | B26: A-1 | C26: 1400000000 | D26: =$B$14 | E26: =$B$6 | F26: =$B$7 | G26: =ROUNDDOWN(C26*D26*E26/F26,0) | H26: Tranche A 이자유보계좌 1005-504-965088
A27: 금모래신용협동조합 | B27: A-1 | C27: 1800000000 | D27: =$B$14 | E27: =$B$6 | F27: =$B$7 | G27: =ROUNDDOWN(C27*D27*E27/F27,0) | H27: Tranche A 이자유보계좌 1005-504-965088
A28: 남인천신용협동조합 | B28: A-1 | C28: 1000000000 | D28: =$B$14 | E28: =$B$6 | F28: =$B$7 | G28: =ROUNDDOWN(C28*D28*E28/F28,0) | H28: Tranche A 이자유보계좌 1005-504-965088
A29: 미호신용협동조합 | B29: A-1 | C29: 1300000000 | D29: =$B$14 | E29: =$B$6 | F29: =$B$7 | G29: =ROUNDDOWN(C29*D29*E29/F29,0) | H29: Tranche A 이자유보계좌 1005-504-965088
A30: 대구대서신용협동조합 | B30: A-1 | C30: 1300000000 | D30: =$B$14 | E30: =$B$6 | F30: =$B$7 | G30: =ROUNDDOWN(C30*D30*E30/F30,0) | H30: Tranche A 이자유보계좌 1005-504-965088
A31: 한빛신용협동조합 | B31: A-1 | C31: 1700000000 | D31: =$B$14 | E31: =$B$6 | F31: =$B$7 | G31: =ROUNDDOWN(C31*D31*E31/F31,0) | H31: Tranche A 이자유보계좌 1005-504-965088
... A40: (주)에스비아이저축은행 | B40: A-1 | C40: 10000000000 | D40: =$B$14 | E40: =$B$6 | F40: =$B$7 | G40: =ROUNDDOWN(C40*D40*E40/F40,0) | H40: Tranche A 이자유보계좌 1005-504-965088
A41: (주)우리은행 | B41: A-2 | C41: 70000000000 | D41: =$B$15 | E41: =$B$6 | F41: =$B$7 | G41: =ROUNDDOWN(C41*D41*E41/F41,0) | H41: Tranche A 이자유보계좌 1005-504-965088
A42: 키움캐피탈(주) | B42: B | C42: 20000000000 | D42: =$B$16 | E42: =$B$6 | F42: =$B$7 | G42: =ROUNDDOWN(C42*D42*E42/F42,0) | H42: Tranche B 이자유보계좌 1005-504-970089
A43: 엠지캐피탈(주) | B43: B | C43: 10000000000 | D43: =$B$16 | E43: =$B$6 | F43: =$B$7 | G43: =ROUNDDOWN(C43*D43*E43/F43,0) | H43: Tranche B 이자유보계좌 1005-504-970089
A44: (주)디비저축은행 | B44: B | C44: 8000000000 | D44: =$B$16 | E44: =$B$6 | F44: =$B$7 | G44: =ROUNDDOWN(C44*D44*E44/F44,0) | H44: Tranche B 이자유보계좌 1005-504-970089
A45: Tranche A-1 소계 | C45: =SUMIF($B$20:$B$44,"A-1",$C$20:$C$44) | G45: =SUMIF($B$20:$B$44,"A-1",$G$20:$G$44)
A46: Tranche A-2 소계 | C46: =SUMIF($B$20:$B$44,"A-2",$C$20:$C$44) | G46: =SUMIF($B$20:$B$44,"A-2",$G$20:$G$44)
A47: Tranche B 소계 | C47: =SUMIF($B$20:$B$44,"B",$C$20:$C$44) | G47: =SUMIF($B$20:$B$44,"B",$G$20:$G$44)
A48: Tranche A 이자적립금 (A-1 + A-2) → 1005-504-965088 | C48: =C45+C46 | G48: =G45+G46
A49: Tranche B 이자적립금 → 1005-504-970089 | C49: =C47 | G49: =G47
A50: 이자적립금 합계 | C50: =C48+C49 | G50: =G48+G49
...
