Workbook

Sheet 통합 통지처
A1: 안양 물류센터 담보대출 – 대주별 참여금액 및 통지처 (선순위·중순위 통합)
G2: (단위: 억원)
A3: 순위 | B3: 구분 | C3: 대주명 | D3: 해당 | E3: 금액 | F3: 비중 | G3: 통지처
A4: 선순위 | B4: =1 -> 1 | C4: 우리은행 | D4: =선순위!C36 -> Tr.A-2 (변동금리) | E4: =선순위!D36 -> 700 | F4: =E4/$E$31 -> 0.35353535 | G4: =선순위!E36 -> 주소 : 서울특별시 영등포구 여의대로 108, 34층(의의도동, 파크원) 전화번호 : 02-2002-5921 / 02-2002-4567 담당자 / 이인환 과장 / 홍진경 과장 Email : gsk3150@wooribank.com / jkhong@wooribank.com
B5: =B4+1 -> 2 | C5: 롯데캐피탈 | D5: =선순위!C37 -> Tr.A-1 (고정금리) | E5: =선순위!D37 -> 300 | F5: =E5/$E$31 -> 0.15151515 | G5: =선순위!E37 -> 주소 : 서울시 강남구 테헤란로 142 ARC PLACE 9층 전화번호 : 02-3451-0168/ 010-9872-2219 담당자 : 곽경호 책임 Email : kyungho.kwak@lotte.net, lottecap_corp3@lotte.net
B6: =B5+1 -> 3 | C6: 우리카드 | D6: =선순위!C38 -> Tr.A-1 (고정금리) | E6: =선순위!D38 -> 100 | F6: =E6/$E$31 -> 0.050505051 | G6: =선순위!E38 -> 주소: 서울특별시 종로구 종로1길50(중학동) 케이트윈타워 A동 전화번호: 02-6968-3531 / 010-9764-8118 팩스번호: 0505-001-8544 담당자: 강민구 과장 Email: kangmg@wooricard.com
B7: =B6+1 -> 4 | C7: 수협은행 | D7: =선순위!C39 -> Tr.A-1 (고정금리) | E7: =선순위!D39 -> 100 | F7: =E7/$E$31 -> 0.050505051 | G7: =선순위!E39 -> 주소: 서울특별시 동작구 동작대로 43 ,1층 수협은행 사당역지점 전화번호: 02-874-8781(내선:4518) / 010-6828-8205 팩스번호: 02-585-7745 담당자: 이진용 대리 Email: rinyong2@suhyup-bank.com
B8: =B7+1 -> 5 | C8: SBI저축은행 | D8: =선순위!C40 -> Tr.A-1 (고정금리) | E8: =선순위!D40 -> 100 | F8: =E8/$E$31 -> 0.050505051 | G8: =선순위!E40 -> 주소: 서울시 중구 을지로 5길 26, 9층 (수하동, 미래에셋센터원빌딩 동관) 전화번호: 02-3416-4828 / 010-9158-6842 팩스번호: 02-2136-0293 담당자: 이정민 매니저 Email: ljm88@sbisb.co.kr
B9: =B8+1 -> 6 | C9: 신용협동조합중앙회 | D9: =선순위!C41 -> Tr.A-1 (고정금리) | E9: =선순위!D41 -> 1 | F9: =E9/$E$31 -> 0.00050505051 | G9: =선순위!E41 -> 주소 : 서울특별시 중구 소월로 10 단암빌딩 14층 전화번호 : 02.590.5849 / 010.2241.1820 담당자 : 안소진 대리 / 투자관리 Email : sjahn@cu.co.kr / cuf1803@cu.co.kr 수취계좌 : 농협 081-01-168860 / 예금주 : 신협중앙회
B10: =B9+1 -> 7 | C10: 서로신용협동조합(주간) | D10: =선순위!C42 -> Tr.A-1 (고정금리) | E10: =선순위!D42 -> 40 | F10: =E10/$E$31 -> 0.02020202 | G10: =선순위!E42 -> 주소 : 인천광역시 서해구 가정로 288(석남동) 전화번호 : 032.574.0166 / 010.7152.5264 담당자 : 장성진 과장 Email : SJin87@cu.co.kr 수취계좌 : 신협 131-000-941666 / 예금주 : 서로신용협동조합
B11: =B10+1 -> 8 | C11: 수지신용협동조합 | D11: =선순위!C43 -> Tr.A-1 (고정금리) | E11: =선순위!D43 -> 28 | F11: =E11/$E$31 -> 0.014141414 | G11: =선순위!E43 -> 주소 : 경기도 용인시 수지구 문정로 7번길 8 1층 전화번호 : 031.262.6801 / 010.7143.7369 담당자 : 권영욱 대리 Email : suji_youngwook@naver.com 수취계좌 : 신협 131-014-493393 / 예금주 : 수지신협
B12: =B11+1 -> 9 | C12: 정선신용협동조합 | D12: =선순위!C44 -> Tr.A-1 (고정금리) | E12: =선순위!D44 -> 24 | F12: =E12/$E$31 -> 0.012121212 | G12: =선순위!E44 -> 주소 : 강원특별자치도 정선군 정선읍 봉양6길 31 전화번호 : 033.563.0760 / 010.6679.3464 담당자 : 장용현 주임 Email : cu04008@cu.co.kr 수취계좌 : 신협 131-019-058167 / 예금주 : 정선신용협동조합
B13: =B12+1 -> 10 | C13: 연희신용협동조합 | D13: =선순위!C45 -> Tr.A-1 (고정금리) | E13: =선순위!D45 -> 14 | F13: =E13/$E$31 -> 0.0070707071 | G13: =선순위!E45 -> 주소 : 서울특별시 서대문구 연희로 64-22 전화번호 : 02.323.2636 / 010.6519.0830 , 010.8467.2620 담당자 : 양주성 과장, 박준희 대리 Email : cu01221@cu.co.kr 수취계좌 : 신협 131-000-189579 / 예금주 : 연희신협
B14: =B13+1 -> 11 | C14: 금모래신용협동조합 | D14: =선순위!C46 -> Tr.A-1 (고정금리) | E14: =선순위!D46 -> 18 | F14: =E14/$E$31 -> 0.0090909091 | G14: =선순위!E46 -> 주소 : 서울시 서대문구 가재울미래로 11 (남가좌동) 전화번호 : 02.376.2036 / 010.2527.0576 담당자 : 정덕호 주임 Email : jeong0576@cu.co.kr 수취계좌 : 신협 131-000-001170 / 예금주 : 금모래신협
B15: =B14+1 -> 12 | C15: 남인천신용협동조합 | D15: =선순위!C47 -> Tr.A-1 (고정금리) | E15: =선순위!D47 -> 10 | F15: =E15/$E$31 -> 0.0050505051 | G15: =선순위!E47 -> 주소 : 인천시 부평구 배곶로 64 전화번호 : 032.437.9563 / 010.2006.7819 담당자 : 임인희 차장 Email : hee4977@cu.co.kr 수취계좌 : 신협 131-000-942952 / 예금주 : 남인천신협
B16: =B15+1 -> 13 | C16: 미호신용협동조합 | D16: =선순위!C48 -> Tr.A-1 (고정금리) | E16: =선순위!D48 -> 13 | F16: =E16/$E$31 -> 0.0065656566 | G16: =선순위!E48 -> 주소 : 충청도 청주시 흥덕구 강내면 태성탑연로 448-10 전화번호 : 043.232.2652 / 010.7735.5225 담당자 : 이주희 차장 Email : cu05053@cu.co.kr 수취계좌 : 신협 131-002-821894 / 예금주 : 미호신협
... B25: =B24+1 -> 22 | C25: 북인천신용협동조합 | D25: =선순위!C57 -> Tr.A-1 (고정금리) | E25: =선순위!D57 -> 7 | F25: =E25/$E$31 -> 0.0035353535 | G25: =선순위!E57 -> 주소 : 인천광역시 부평구 후정로 8, 상가2동 B04호 전화번호 : 032.516.8101 / 010.9664.0702 담당자 : 김희승 과장 Email : kkhs101@nate.com / cu03236@cu.co.kr 수취계좌 : 신협 131-002-051950 / 예금주: 북인천신용협동조합
A26: 선순위 소계 | E26: =SUM(E4:E25) -> 1600 | F26: =E26/$E$31 -> 0.80808081
A27: 중순위 | B27: =1 -> 1 | C27: 키움캐피탈 | D27: - | E27: =중순위!C25/100000000 -> 200 | F27: =E27/$E$31 -> 0.1010101 | G27: =중순위!D25 -> 주소: 서울특별시 영등포구 여의대로 66, 17층 전화번호: 02-780-4295 / 010-4339-3878 팩스번호: 02-780-1517 담당자: 이승근 주임 전자우편: tmd283@kiwoomcapital.com
B28: =B27+1 -> 2 | C28: 엠지캐피탈 | D28: - | E28: =중순위!C26/100000000 -> 100 | F28: =E28/$E$31 -> 0.050505051 | G28: =중순위!D26 -> 주소: 서울특별시 중구 남대문로 55, MG파이낸스센터 12층 전화번호: 02-2200-7423 / 010-5241-8897 팩스번호: 02-511-3021 담당자: 박소현 과장 전자우편: sopark@mgcap.co.kr
B29: =B28+1 -> 3 | C29: 디비저축은행 | D29: - | E29: =중순위!C27/100000000 -> 80 | F29: =E29/$E$31 -> 0.04040404 | G29: =중순위!D27 -> 주소: 서울특별시 중구 남대문로 113, 다동 전화번호: 02-3705-1759 / 010-4440-4730 팩스번호: 02-3705-1850 담당자: 정성범 선임 전자우편: seongbeom4730j@dbgroup.co.kr
A30: 중순위 소계 | E30: =SUM(E27:E29) -> 380 | F30: =E30/$E$31 -> 0.19191919
A31: 합계 | E31: =E26+E30 -> 1980 | F31: =E31/$E$31 -> 1

Sheet 선순위
A1: 구분 | B1: 예상 참여 | C1: Tr.A-1(고정) | D1: Tr.A-2(변동) | E1: 금리(26.10.12기준) | F1: All-in(참여) | G1: 참여수수료 | H1: 주선수수료 | I1: 주선 | J1: 대주 | K1: 쿠폰 | L1: 주선수수료 | R1: 취급수수료 | S1: 주선
A2: 우리은행 | B2: 700 | D2: o | E2: 4.67(CD+1.43) | F2: 5.07 | G2: 560 | H2: 850 | I2: =J2+L2 -> 5.42 | J2: =K2+0.4 -> 5.07 | K2: 4.67 | L2: 0.35 | M2: =B2/$B$9 -> 0.4375 | N2: =I2*M2 -> 2.37125 | O2: =I2-K2 -> 0.75 | P2: =O2*2 -> 1.5 | Q2: =P2*B2 -> 1050 | R2: =(J2-K2)*B2*2 -> 560 | S2: =B2*L2*2 -> 490 | T2: =S2+R2 -> 1050 | U2: =B2/$B$9*I2 -> 2.37125
A3: 롯데캐피탈 | B3: 300 | C3: o | E3: 5 | F3: 5.9 | G3: 540 | I3: =J3+L3 -> 6.1 | J3: 5.9 | K3: 5 | L3: 0.2 | M3: =B3/$B$9 -> 0.1875 | N3: =I3*M3 -> 1.14375 | O3: =I3-K3 -> 1.1 | P3: =O3*2 -> 2.2 | Q3: =P3*B3 -> 660 | R3: =(J3-K3)*B3*2 -> 540 | S3: =B3*L3*2 -> 120 | T3: =S3+R3 -> 660 | U3: =B3/$B$9*I3 -> 1.14375
A4: 우리카드 | B4: 100 | C4: o | E4: 5 | F4: 5.6 | G4: 120 | I4: =J4+L4 -> 5.8 | J4: 5.6 | K4: 5 | L4: 0.2 | M4: =B4/$B$9 -> 0.0625 | N4: =I4*M4 -> 0.3625 | O4: =I4-K4 -> 0.8 | P4: =O4*2 -> 1.6 | Q4: =P4*B4 -> 160 | R4: =(J4-K4)*B4*2 -> 120 | S4: =B4*L4*2 -> 40 | T4: =S4+R4 -> 160 | U4: =B4/$B$9*I4 -> 0.3625
A5: 신협중앙회 | B5: 300 | C5: o | E5: 5 | F5: 5.5 | G5: 300 | I5: =J5+L5 -> 5.7 | J5: 5.5 | K5: 5 | L5: 0.2 | M5: =B5/$B$9 -> 0.1875 | N5: =I5*M5 -> 1.06875 | O5: =I5-K5 -> 0.7 | P5: =O5*2 -> 1.4 | Q5: =P5*B5 -> 420 | R5: =(J5-K5)*B5*2 -> 300 | S5: =B5*L5*2 -> 120 | T5: =S5+R5 -> 420 | U5: =B5/$B$9*I5 -> 1.06875
A6: 수협은행 | B6: 100 | C6: o | E6: 5 | F6: 5.5 | G6: 100 | I6: =J6+L6 -> 5.7 | J6: 5.5 | K6: 5 | L6: 0.2 | M6: =B6/$B$9 -> 0.0625 | N6: =I6*M6 -> 0.35625 | O6: =I6-K6 -> 0.7 | P6: =O6*2 -> 1.4 | Q6: =P6*B6 -> 140 | R6: =(J6-K6)*B6*2 -> 100 | S6: =B6*L6*2 -> 40 | T6: =S6+R6 -> 140 | U6: =B6/$B$9*I6 -> 0.35625
A7: SBI저축은행 | B7: 100 | C7: o | E7: 5 | F7: 5.5 | G7: 100 | I7: =J7+L7 -> 5.7 | J7: 5.5 | K7: 5 | L7: 0.2 | M7: =B7/$B$9 -> 0.0625 | N7: =I7*M7 -> 0.35625 | O7: =I7-K7 -> 0.7 | P7: =O7*2 -> 1.4 | Q7: =P7*B7 -> 140 | R7: =(J7-K7)*B7*2 -> 100 | S7: =B7*L7*2 -> 40 | T7: =S7+R7 -> 140 | U7: =B7/$B$9*I7 -> 0.35625
M8: =B8/$B$9 -> 0 | N8: =I8*M8 -> 0 | O8: =J8-K8+L8 -> 0 | P8: =O8*2 -> 0 | Q8: =P8*B8 -> 0 | U8: =SUM(U2:U7) -> 5.65875
A9: 합계 | B9: =SUM(B2:B8) -> 1600 | G9: =SUM(G2:G8) -> 1720 | H9: =H2 -> 850 | M9: =B9/$B$9 -> 1 | N9: =I9*M9 -> 0 | O9: =J9-K9+L9 -> 0 | P9: =O9*2 -> 0 | Q9: =P9*B9 -> 0 | R9: =SUM(R2:R8) -> 1720 | S9: =SUM(S2:S8) -> 850
A10: ※ 당행 물량중 [400]억원은 기표후 셀다운 예정 | G10: 수수료합계 | H10: =G9+H9 -> 2570 | O10: =J10-K10+L10 -> 0 | P10: =O10*2 -> 0 | Q10: =P10*B10 -> 0 | S10: =R9+S9 -> 2570
M11: =B11/$B$9 -> 0 | N11: =I11*M11 -> 0 | O11: =I11-K11 -> 0 | P11: =O11*2 -> 0 | Q11: =P11*B11 -> 0 | R11: =(J11-K11)*B11*2 -> 0 | S11: =B11*L11*2 -> 0
G12: All-in | H12: =U8 -> 5.65875
F14: 24
A16: 구분 | B16: 예상 참여 | C16: Tr.A-1(고정) | D16: 금리(26.10.12기준) | E16: All-in(참여) | F16: 참여수수료 | G16: 주선수수료 | H16: 대주 | I16: All-in | R16: 구분 | S16: 본약정 | T16: 대안
A17: 우리은행 | B17: 700 | D17: 0.0467 | E17: =F2/100 -> 0.0507 | F17: =G2/B17/100 -> 0.008 | G17: =IFERROR(H2/B17/100,) -> 0.012142857 | H17: =D17+F17/2 -> 0.0507 | I17: =D17+SUM(F17:G17)/2 -> 0.056771429 | R17: 우리은행 | S17: 700 | T17: 800
A18: 롯데캐피탈 | B18: 300 | C18: o | D18: 0.05 | E18: =F3/100 -> 0.059 | F18: =G3/B18/100 -> 0.018 | G18: =IFERROR(H3/B18/100,) -> 0 | H18: =D18+F18/2 -> 0.059 | I18: =D18+SUM(F18:G18)/2 -> 0.059 | R18: 롯데캐피탈 | S18: 300 | T18: 300
A19: 우리카드 | B19: 100 | C19: o | D19: 0.05 | E19: =F4/100 -> 0.056 | F19: =G4/B19/100 -> 0.012 | G19: =IFERROR(H4/B19/100,) -> 0 | H19: =D19+F19/2 -> 0.056 | I19: =D19+SUM(F19:G19)/2 -> 0.056 | R19: 우리카드 | S19: 100
A20: 신협중앙회 | B20: 300 | C20: o | D20: 0.05 | E20: =F5/100 -> 0.055 | F20: =G5/B20/100 -> 0.01 | G20: =IFERROR(H5/B20/100,) -> 0 | H20: =D20+F20/2 -> 0.055 | I20: =D20+SUM(F20:G20)/2 -> 0.055 | R20: 신협중앙회 | S20: 300 | T20: 300
A21: 수협은행 | B21: 100 | C21: o | D21: 0.05 | E21: =F6/100 -> 0.055 | F21: =G6/B21/100 -> 0.01 | G21: =IFERROR(H6/B21/100,) -> 0 | H21: =D21+F21/2 -> 0.055 | I21: =D21+SUM(F21:G21)/2 -> 0.055 | R21: 수협은행 | S21: 100 | T21: 100
A22: SBI저축은행 | B22: 100 | C22: o | D22: 0.05 | E22: =F7/100 -> 0.055 | F22: =G7/B22/100 -> 0.01 | G22: =IFERROR(H7/B22/100,) -> 0 | H22: =D22+F22/2 -> 0.055 | I22: =D22+SUM(F22:G22)/2 -> 0.055 | R22: SBI저축은행 | S22: 100 | T22: 100
G23: =IFERROR(H8/B23/100,) -> 0 | R23: 합계 | S23: =SUM(S17:S22) -> 1600 | T23: =SUM(T17:T22) -> 1600
A24: 합계 | B24: =SUM(B17:B23) -> 1600 | F24: =SUM(F17:F23) -> 0.068 | G24: =G17 -> 0.012142857 | I24: =SUMPRODUCT(B17:B22,I17:I22)/B24 -> 0.0565875 | R24: Tr.A-1 변동 | S24: =S17 -> 700 | T24: =T17 -> 800
A25: Tr.A-1 변동 | B25: =B17 -> 700 | D25: =D17 -> 0.0467 | E25: =E17 -> 0.0507 | F25: =F17 -> 0.008 | G25: =G17 -> 0.012142857 | H25: =H17 -> 0.0507 | I25: =I17 -> 0.056771429 | R25: Tr.A-1 고정 | S25: =SUM(S18:S22) -> 900 | T25: =T23-T24 -> 800
A26: Tr.A-1 고정 | B26: =SUM(B18:B22) -> 900 | D26: =SUMPRODUCT($B18:$B22,D18:D22)/SUM($B18:$B22) -> 0.05 | E26: =SUMPRODUCT($B18:$B22,E18:E22)/SUM($B18:$B22) -> 0.056444444 | F26: =SUMPRODUCT($B18:$B22,F18:F22)/SUM($B18:$B22) -> 0.012888889 | G26: =SUMPRODUCT($B18:$B22,G18:G22)/SUM($B18:$B22) -> 0 | H26: =SUMPRODUCT($B18:$B22,H18:H22)/SUM($B18:$B22) -> 0.056444444 | I26: =SUMPRODUCT($B18:$B22,I18:I22)/SUM($B18:$B22) -> 0.056444444 | R26: 변동조건 | S26: CD+143bp | T26: CD+143bp
R27: 고정 | S27: 0.05 | T27: 0.05
A34: ■통지처
A35: 구분 | B35: 대주명 | C35: 해당 | D35: 금액 | E35: 통지처
A36: 1 | B36: 우리은행 | C36: Tr.A-2 (변동금리) | D36: 700 | E36: 주소 : 서울특별시 영등포구 여의대로 108, 34층(의의도동, 파크원) 전화번호 : 02-2002-5921 / 02-2002-4567 담당자 / 이인환 과장 / 홍진경 과장 Email : gsk3150@wooribank.com / jkhong@wooribank.com
A37: 2 | B37: 롯데캐피탈 | C37: Tr.A-1 (고정금리) | D37: 300 | E37: 주소 : 서울시 강남구 테헤란로 142 ARC PLACE 9층 전화번호 : 02-3451-0168/ 010-9872-2219 담당자 : 곽경호 책임 Email : kyungho.kwak@lotte.net, lottecap_corp3@lotte.net
A38: 3 | B38: 우리카드 | C38: Tr.A-1 (고정금리) | D38: 100 | E38: 주소: 서울특별시 종로구 종로1길50(중학동) 케이트윈타워 A동 전화번호: 02-6968-3531 / 010-9764-8118 팩스번호: 0505-001-8544 담당자: 강민구 과장 Email: kangmg@wooricard.com
A39: =A38+1 -> 4 | B39: 수협은행 | C39: Tr.A-1 (고정금리) | D39: 100 | E39: 주소: 서울특별시 동작구 동작대로 43 ,1층 수협은행 사당역지점 전화번호: 02-874-8781(내선:4518) / 010-6828-8205 팩스번호: 02-585-7745 담당자: 이진용 대리 Email: rinyong2@suhyup-bank.com
A40: =A39+1 -> 5 | B40: SBI저축은행 | C40: Tr.A-1 (고정금리) | D40: 100 | E40: 주소: 서울시 중구 을지로 5길 26, 9층 (수하동, 미래에셋센터원빌딩 동관) 전화번호: 02-3416-4828 / 010-9158-6842 팩스번호: 02-2136-0293 담당자: 이정민 매니저 Email: ljm88@sbisb.co.kr
A41: =A40+1 -> 6 | B41: ='신협통지처(최종)'!B4 -> 신용협동조합중앙회 | C41: Tr.A-1 (고정금리) | D41: ='신협통지처(최종)'!C4 -> 1 | E41: ="주소 : "&'신협통지처(최종)'!F4&CHAR(10)&"전화번호 : "&'신협통지처(최종)'!J4&" / "&'신협통지처(최종)'!K4&CHAR(10)&"담당자 : "&'신협통지처(최종)'!G4&CHAR(10)&"Email : "&'신협통지처(최종)'!L4&CHAR(10)&"수취계좌 : "&'신협통지처(최종)'!M4 -> 주소 : 서울특별시 중구 소월로 10 단암빌딩 14층 전화번호 : 02.590.5849 / 010.2241.1820 담당자 : 안소진 대리 / 투자관리 Email : sjahn@cu.co.kr / cuf1803@cu.co.kr 수취계좌 : 농협 081-01-168860 / 예금주 : 신협중앙회
A42: =A41+1 -> 7 | B42: ='신협통지처(최종)'!B5 -> 서로신용협동조합(주간) | C42: Tr.A-1 (고정금리) | D42: ='신협통지처(최종)'!C5 -> 40 | E42: ="주소 : "&'신협통지처(최종)'!F5&CHAR(10)&"전화번호 : "&'신협통지처(최종)'!J5&" / "&'신협통지처(최종)'!K5&CHAR(10)&"담당자 : "&'신협통지처(최종)'!G5&CHAR(10)&"Email : "&'신협통지처(최종)'!L5&CHAR(10)&"수취계좌 : "&'신협통지처(최종)'!M5 -> 주소 : 인천광역시 서해구 가정로 288(석남동) 전화번호 : 032.574.0166 / 010.7152.5264 담당자 : 장성진 과장 Email : SJin87@cu.co.kr 수취계좌 : 신협 131-000-941666 / 예금주 : 서로신용협동조합
A43: =A42+1 -> 8 | B43: ='신협통지처(최종)'!B6 -> 수지신용협동조합 | C43: Tr.A-1 (고정금리) | D43: ='신협통지처(최종)'!C6 -> 28 | E43: ="주소 : "&'신협통지처(최종)'!F6&CHAR(10)&"전화번호 : "&'신협통지처(최종)'!J6&" / "&'신협통지처(최종)'!K6&CHAR(10)&"담당자 : "&'신협통지처(최종)'!G6&CHAR(10)&"Email : "&'신협통지처(최종)'!L6&CHAR(10)&"수취계좌 : "&'신협통지처(최종)'!M6 -> 주소 : 경기도 용인시 수지구 문정로 7번길 8 1층 전화번호 : 031.262.6801 / 010.7143.7369 담당자 : 권영욱 대리 Email : suji_youngwook@naver.com 수취계좌 : 신협 131-014-493393 / 예금주 : 수지신협
A44: =A43+1 -> 9 | B44: ='신협통지처(최종)'!B7 -> 정선신용협동조합 | C44: Tr.A-1 (고정금리) | D44: ='신협통지처(최종)'!C7 -> 24 | E44: ="주소 : "&'신협통지처(최종)'!F7&CHAR(10)&"전화번호 : "&'신협통지처(최종)'!J7&" / "&'신협통지처(최종)'!K7&CHAR(10)&"담당자 : "&'신협통지처(최종)'!G7&CHAR(10)&"Email : "&'신협통지처(최종)'!L7&CHAR(10)&"수취계좌 : "&'신협통지처(최종)'!M7 -> 주소 : 강원특별자치도 정선군 정선읍 봉양6길 31 전화번호 : 033.563.0760 / 010.6679.3464 담당자 : 장용현 주임 Email : cu04008@cu.co.kr 수취계좌 : 신협 131-019-058167 / 예금주 : 정선신용협동조합
A45: =A44+1 -> 10 | B45: ='신협통지처(최종)'!B8 -> 연희신용협동조합 | C45: Tr.A-1 (고정금리) | D45: ='신협통지처(최종)'!C8 -> 14 | E45: ="주소 : "&'신협통지처(최종)'!F8&CHAR(10)&"전화번호 : "&'신협통지처(최종)'!J8&" / "&'신협통지처(최종)'!K8&CHAR(10)&"담당자 : "&'신협통지처(최종)'!G8&CHAR(10)&"Email : "&'신협통지처(최종)'!L8&CHAR(10)&"수취계좌 : "&'신협통지처(최종)'!M8 -> 주소 : 서울특별시 서대문구 연희로 64-22 전화번호 : 02.323.2636 / 010.6519.0830 , 010.8467.2620 담당자 : 양주성 과장, 박준희 대리 Email : cu01221@cu.co.kr 수취계좌 : 신협 131-000-189579 / 예금주 : 연희신협
A46: =A45+1 -> 11 | B46: ='신협통지처(최종)'!B9 -> 금모래신용협동조합 | C46: Tr.A-1 (고정금리) | D46: ='신협통지처(최종)'!C9 -> 18 | E46: ="주소 : "&'신협통지처(최종)'!F9&CHAR(10)&"전화번호 : "&'신협통지처(최종)'!J9&" / "&'신협통지처(최종)'!K9&CHAR(10)&"담당자 : "&'신협통지처(최종)'!G9&CHAR(10)&"Email : "&'신협통지처(최종)'!L9&CHAR(10)&"수취계좌 : "&'신협통지처(최종)'!M9 -> 주소 : 서울시 서대문구 가재울미래로 11 (남가좌동) 전화번호 : 02.376.2036 / 010.2527.0576 담당자 : 정덕호 주임 Email : jeong0576@cu.co.kr 수취계좌 : 신협 131-000-001170 / 예금주 : 금모래신협
A47: =A46+1 -> 12 | B47: ='신협통지처(최종)'!B10 -> 남인천신용협동조합 | C47: Tr.A-1 (고정금리) | D47: ='신협통지처(최종)'!C10 -> 10 | E47: ="주소 : "&'신협통지처(최종)'!F10&CHAR(10)&"전화번호 : "&'신협통지처(최종)'!J10&" / "&'신협통지처(최종)'!K10&CHAR(10)&"담당자 : "&'신협통지처(최종)'!G10&CHAR(10)&"Email : "&'신협통지처(최종)'!L10&CHAR(10)&"수취계좌 : "&'신협통지처(최종)'!M10 -> 주소 : 인천시 부평구 배곶로 64 전화번호 : 032.437.9563 / 010.2006.7819 담당자 : 임인희 차장 Email : hee4977@cu.co.kr 수취계좌 : 신협 131-000-942952 / 예금주 : 남인천신협
A48: =A47+1 -> 13 | B48: ='신협통지처(최종)'!B11 -> 미호신용협동조합 | C48: Tr.A-1 (고정금리) | D48: ='신협통지처(최종)'!C11 -> 13 | E48: ="주소 : "&'신협통지처(최종)'!F11&CHAR(10)&"전화번호 : "&'신협통지처(최종)'!J11&" / "&'신협통지처(최종)'!K11&CHAR(10)&"담당자 : "&'신협통지처(최종)'!G11&CHAR(10)&"Email : "&'신협통지처(최종)'!L11&CHAR(10)&"수취계좌 : "&'신협통지처(최종)'!M11 -> 주소 : 충청도 청주시 흥덕구 강내면 태성탑연로 448-10 전화번호 : 043.232.2652 / 010.7735.5225 담당자 : 이주희 차장 Email : cu05053@cu.co.kr 수취계좌 : 신협 131-002-821894 / 예금주 : 미호신협
...

Sheet 신협통지처(최종)
A1: 안양 물류센터 담보대출
M2: (단위: 억원)
A3: 연번 | B3: 법인명 | C3: 신규 가능 금액(억원) | D3: 조합인가번호 | E3: 대표자명 | F3: 주소 | G3: 담당자(실무자) | H3: 사업자등록번호 | I3: 법인등록번호 | J3: 전화번호 | K3: 휴대폰 연락처 | L3: 메일주소 | M3: 원리금 및 수수료 수취 계좌
A4: 1 | B4: 신용협동조합중앙회 | C4: 1 | D4: 48000 | E4: 신용공제사업대표이사 손성은 | F4: 서울특별시 중구 소월로 10 단암빌딩 14층 | G4: 안소진 대리 / 투자관리 | H4: 114-82-08554 | I4: 115041-0000361 | J4: 02.590.5849 | K4: 010.2241.1820 | L4: sjahn@cu.co.kr / cuf1803@cu.co.kr | M4: 농협 081-01-168860 / 예금주 : 신협중앙회
A5: 2 | B5: 서로신용협동조합(주간) | C5: 40 | D5: 03094 | E5: 이사장 윤정섭 | F5: 인천광역시 서해구 가정로 288(석남동) | G5: 장성진 과장 | H5: 137-82-01229 | I5: 124141-0000912 | J5: 032.574.0166 | K5: 010.7152.5264 | L5: SJin87@cu.co.kr | M5: 신협 131-000-941666 / 예금주 : 서로신용협동조합
A6: 3 | B6: 수지신용협동조합 | C6: 28 | D6: 03249 | E6: 이사장 이기찬 | F6: 경기도 용인시 수지구 문정로 7번길 8 1층 | G6: 권영욱 대리 | H6: 135-82-06854 | I6: 134541-0000251 | J6: 031.262.6801 | K6: 010.7143.7369 | L6: suji_youngwook@naver.com | M6: 신협 131-014-493393 / 예금주 : 수지신협
A7: 4 | B7: 정선신용협동조합 | C7: 24 | D7: 04008 | E7: 이사장 김동기 | F7: 강원특별자치도 정선군 정선읍 봉양6길 31 | G7: 장용현 주임 | H7: 225-82-00696 | I7: 144941-0000813 | J7: 033.563.0760 | K7: 010.6679.3464 | L7: cu04008@cu.co.kr | M7: 신협 131-019-058167 / 예금주 : 정선신용협동조합
A8: 5 | B8: 연희신용협동조합 | C8: 14 | D8: 01221 | E8: 이사장 박영철 | F8: 서울특별시 서대문구 연희로 64-22 | G8: 양주성 과장, 박준희 대리 | H8: 111-82-02245 | I8: 114544-0000548 | J8: 02.323.2636 | K8: 010.6519.0830 , 010.8467.2620 | L8: cu01221@cu.co.kr | M8: 신협 131-000-189579 / 예금주 : 연희신협
A9: 6 | B9: 금모래신용협동조합 | C9: 18 | D9: 01003 | E9: 이사장 최성묵 | F9: 서울시 서대문구 가재울미래로 11 (남가좌동) | G9: 정덕호 주임 | H9: 111-82-00378 | I9: 114541-0000205 | J9: 02.376.2036 | K9: 010.2527.0576 | L9: jeong0576@cu.co.kr | M9: 신협 131-000-001170 / 예금주 : 금모래신협
A10: 7 | B10: 남인천신용협동조합 | C10: 10 | D10: 03099 | E10: 이사장 전재호 | F10: 인천시 부평구 배곶로 64 | G10: 임인희 차장 | H10: 137-82-01078 | I10: 124246-0000663 | J10: 032.437.9563 | K10: 010.2006.7819 | L10: hee4977@cu.co.kr | M10: 신협 131-000-942952 / 예금주 : 남인천신협
A11: 8 | B11: 미호신용협동조합 | C11: 13 | D11: 05053 | E11: 이사장 고동준 | F11: 충청도 청주시 흥덕구 강내면 태성탑연로 448-10 | G11: 이주희 차장 | H11: 301-82-02402 | I11: 150141-0004293 | J11: 043.232.2652 | K11: 010.7735.5225 | L11: cu05053@cu.co.kr | M11: 신협 131-002-821894 / 예금주 : 미호신협
A12: 9 | B12: 대구대서신용협동조합 | C12: 13 | D12: 09301 | E12: 이사장 최영훈 | F12: 대구 서구 서대구로305, 1층 | G12: 곽경열 대리 | H12: 503-82-07681 | I12: 174241-0001330 | J12: 053.351.9500 | K12: 010.8740.2848 | L12: kklcome@cu.co.kr | M12: 신협 131-005-005290 / 예금주 : 대구대서신용협동조합
A13: 10 | B13: 한빛신용협동조합 | C13: 17 | D13: 06195 | E13: 이사장 윤성기 | F13: 대전 대덕구 계족산로81번길 87 | G13: 구진숙 차장 | H13: 306-82-06946 | I13: 164141-0000724 | J13: 042.627.4501 | K13: 010.6608.1804 | L13: cjlover1804@cu.co.kr | M13: 신협 131-003-657209 / 예금주: 한빛신용협동좝
A14: 11 | B14: 양동행복신용협동조합 | C14: 19 | D14: 08076 | E14: 이사장 김영호 | F14: 전남광주통합특별시 서구 천변좌로 238(양동) | G14: 안혜진 과장 | H14: 410-82-02007 | I14: 200141-0001719 | J14: 062.454.6514 | K14: 010.5694.2003 | L14: 080762002002@cu.co.kr | M14: 신협 131-021-819738 / 예금주: 양동행복신용협동조합
A15: 12 | B15: 서귀포동부신용협동조합 | C15: 12 | D15: 11008 | E15: 이사장 현학열 | F15: 제주특별자치도 서귀포시 효돈로 136 | G15: 홍영기 대리 | H15: 616-82-01095 | I15: 224141-0000854 | J15: 064.767.2820 | K15: 010.7564.0888 | L15: cu11008@cu.co.kr | M15: 신협 131-005-410020 / 예금주 : 서귀포동부신협
A16: 13 | B16: 광주어룡신용협동조합 | C16: 27 | D16: 08172 | E16: 이사장 김춘석 | F16: 전남광주통합특별시 광산구 송정로 15 | G16: 박태훈 대리 | H16: 410-82-08127 | I16: 204241-0000963 | J16: 062.720.8811 | K16: 010.3318.5799 | L16: hoon91@cu.co.kr | M16: 신협 131-004-571106 / 예금주 : 광주어룡신협
... A20: 17 | B20: 북인천신용협동조합 | C20: 7 | D20: 03236 | E20: 이사장 김정섭 | F20: 인천광역시 부평구 후정로 8, 상가2동 B04호 | G20: 김희승 과장 | H20: 122-82-04807 | I20: 124241-0000076 | J20: 032.516.8101 | K20: 010.9664.0702 | L20: kkhs101@nate.com / cu03236@cu.co.kr | M20: 신협 131-002-051950 / 예금주: 북인천신용협동조합
C21: =SUM(C4:C20) -> 300

Sheet 신협통지처
A1: 안양 물류센터 담보대출
M2: (단위: 억원)
A3: 연번 | B3: 법인명 | C3: 신규 가능 금액(억원) | D3: 조합인가번호 | E3: 대표자명 | F3: 주소 | G3: 담당자(실무자) | H3: 사업자등록번호 | I3: 법인등록번호 | J3: 전화번호 | K3: 휴대폰 연락처 | L3: 메일주소 | M3: 원리금 및 수수료 수취 계좌
A4: 1 | B4: 신용협동조합중앙회 | C4: 1 | D4: 48000 | E4: 신용공제사업대표이사 손성은 | F4: 서울특별시 중구 소월로 10 단암빌딩 14층 | G4: 안소진 대리 / 투자관리 | H4: 114-82-08554 | I4: 115041-0000361 | J4: 02.590.5849 | K4: 010.2241.1820 | L4: sjahn@cu.co.kr / cuf1803@cu.co.kr | M4: 농협 081-01-168860 / 예금주 : 신협중앙회
A5: 2 | B5: 서로신용협동조합(주간) | C5: 40 | D5: 03094 | E5: 이사장 윤정섭 | F5: 인천광역시 서해구 가정로 288(석남동) | G5: 장성진 과장 | H5: 137-82-01229 | I5: 124141-0000912 | J5: 032.574.0166 | K5: 010.7152.5264 | L5: SJin87@cu.co.kr | M5: 신협 131-000-941666 / 예금주 : 서로신용협동조합
A6: 3 | B6: 수지신용협동조합 | C6: 28 | D6: 03249 | E6: 이사장 이기찬 | F6: 경기도 용인시 수지구 문정로 7번길 8 1층 | G6: 권영욱 대리 | H6: 135-82-06854 | I6: 134541-0000251 | J6: 031.262.6801 | K6: 010.7143.7369 | L6: suji_youngwook@naver.com | M6: 신협 131-014-493393 / 예금주 : 수지신협
A7: 4 | B7: 정선신용협동조합 | C7: 24 | D7: 04008 | E7: 이사장 김동기 | F7: 강원특별자치도 정선군 정선읍 봉양6길 31 | G7: 장용현 주임 | H7: 225-82-00696 | I7: 144941-0000813 | J7: 033.563.0760 | K7: 010.6679.3464 | L7: cu04008@cu.co.kr | M7: 신협 131-019-058167 / 예금주 : 정선신용협동조합
A8: 5 | B8: 연희신용협동조합 | C8: 14 | D8: 01221 | E8: 이사장 박영철 | F8: 서울특별시 서대문구 연희로 64-22 | G8: 양주성 과장, 박준희 대리 | H8: 111-82-02245 | I8: 114544-0000548 | J8: 02.323.2636 | K8: 010.6519.0830 , 010.8467.2620 | L8: cu01221@cu.co.kr | M8: 신협 131-000-189579 / 예금주 : 연희신협
A9: 6 | B9: 금모래신용협동조합 | C9: 18 | D9: 01003 | E9: 이사장 최성묵 | F9: 서울시 서대문구 가재울미래로 11 (남가좌동) | G9: 정덕호 주임 | H9: 111-82-00378 | I9: 114541-0000205 | J9: 02.376.2036 | K9: 010.2527.0576 | L9: jeong0576@cu.co.kr | M9: 신협 131-000-001170 / 예금주 : 금모래신협
A10: 7 | B10: 남인천신용협동조합 | C10: 10 | D10: 03099 | E10: 이사장 전재호 | F10: 인천시 부평구 배곶로 64 | G10: 임인희 차장 | H10: 137-82-01078 | I10: 124246-0000663 | J10: 032.437.9563 | K10: 010.2006.7819 | L10: hee4977@cu.co.kr | M10: 신협 131-000-942952 / 예금주 : 남인천신협
A11: 8 | B11: 미호신용협동조합 | C11: 13 | D11: 05053 | E11: 이사장 고동준 | F11: 충청도 청주시 흥덕구 강내면 태성탑연로 448-10 | G11: 이주희 차장 | H11: 301-82-02402 | I11: 150141-0004293 | J11: 043.232.2652 | K11: 010.7735.5225 | L11: cu05053@cu.co.kr | M11: 신협 131-002-821894 / 예금주 : 미호신협
A12: 9 | B12: 대구대서신용협동조합 | C12: 13 | D12: 09301 | E12: 이사장 최영훈 | F12: 대구 서구 서대구로305, 1층 | G12: 곽경열 대리 | H12: 503-82-07681 | I12: 174241-0001330 | J12: 053.351.9500 | K12: 010.8740.2848 | L12: kklcome@cu.co.kr | M12: 신협 131-005-005290 / 예금주 : 대구대서신용협동조합
A13: 10 | B13: 한빛신용협동조합 | C13: 17 | D13: 06195 | E13: 이사장 윤성기 | F13: 대전 대덕구 계족산로81번길 87 | G13: 구진숙 차장 | H13: 306-82-06946 | I13: 164141-0000724 | J13: 042.627.4501 | K13: 010.6608.1804 | L13: cjlover1804@cu.co.kr | M13: 신협 131-003-657209 / 예금주: 한빛신용협동좝
A14: 11 | B14: 양동행복신용협동조합 | C14: 19 | D14: 08076 | E14: 이사장 김영호 | F14: 전남광주통합특별시 서구 천변좌로 238(양동) | G14: 안헤진 과장 | H14: 410-82-02007 | I14: 200141-0001719 | J14: 062.454.6514 | K14: 010.5694.2003 | L14: 080762002002@cu.co.kr | M14: 신협 131-021-819738 / 예금주: 양동행복신용협동조합
A15: 12 | B15: 서귀포동부신용협동조합 | C15: 12 | D15: 11008 | E15: 이사장 현학열 | F15: 제주특별자치도 서귀포시 효돈로 136 | G15: 홍영기 대리 | H15: 616-82-01095 | I15: 224141-0000854 | J15: 064.767.2820 | K15: 010.7564.0888 | L15: cu11008@cu.co.kr | M15: 신협 131-005-410020 / 예금주 : 서귀포동부신협
A16: 13 | B16: 광주어룡신용협동조합 | C16: 27 | D16: 08172 | E16: 이사장 김춘석 | F16: 전남광주통합특별시 광산구 송정로 15 | G16: 박태훈 대리 | H16: 410-82-08127 | I16: 204241-0000963 | J16: 062.720.8811 | K16: 010.3318.5799 | L16: hoon91@cu.co.kr | M16: 신협 131-004-571106 / 예금주 : 광주어룡신협
... A20: 17 | B20: 북인천신용협동조합 | C20: 7 | D20: 03236 | E20: 이사장 김정섭 | F20: 인천광역시 부평구 후정로 8, 상가2동 B04호 | G20: 김희승 과장 | H20: 122-82-04807 | I20: 124241-0000076 | J20: 032.516.8101 | K20: 010.9664.0702 | L20: kkhs101@nate.com / cu03236@cu.co.kr | M20: 신협 131-002-051950 / 예금주: 북인천신용협동조합
C21: =SUM(C4:C20) -> 300

Sheet 중순위
A1: ■수수료 | F1: 만기 | G1: 2
A2: [기본 조건]
A3: 구분 | B3: 대주명 | C3: 금액 | D3: 금리 | E3: 수수료 | F3: 올인 | H3: 수수료금액
A4: 1 | B4: 키움캐피탈 | C4: 20000000000 | D4: 0.06 | E4: 0.01 | F4: =D4+E4/$G$1 -> 0.065 | H4: =C4*E4 -> 200000000
A5: 2 | B5: 엠지캐피탈 | C5: 10000000000 | D5: 0.06 | E5: 0.01 | F5: =D5+E5/$G$1 -> 0.065 | H5: =C5*E5 -> 100000000
A6: 3 | B6: 디비저축은행 | C6: 8000000000 | D6: 0.06 | E6: 0.01 | F6: =D6+E6/$G$1 -> 0.065 | H6: =C6*E6 -> 80000000
A7: 합계 | C7: =SUM(C4:C6) -> 38000000000
A9: [약정서 반영]
A10: *중순위 대출 취급수수료
A11: 구분 | B11: 대주명 | C11: 금액 | D11: 금리 | E11: 수수료 | F11: 올인 | H11: 수수료금액
A12: 1 | B12: 키움캐피탈 | C12: 20000000000 | D12: 0.06 | E12: 0.01 | F12: =D12+E12/$G$1 -> 0.065 | H12: =C12*E12 -> 200000000
A13: 2 | B13: 엠지캐피탈 | C13: 10000000000 | D13: 0.06 | E13: 0.0064 | F13: =D13+E13/$G$1 -> 0.0632 | H13: =C13*E13 -> 64000000
A14: 3 | B14: 디비저축은행 | C14: 8000000000 | D14: 0.06 | E14: 0.01 | F14: =D14+E14/$G$1 -> 0.065 | H14: =C14*E14 -> 80000000
A15: 합계 | C15: =SUM(C12:C14) -> 38000000000
A17: *1종 인수수수료
A18: 구분 | B18: 대주명 | C18: 금액 | E18: 수수료 | F18: 올인 | H18: 수수료금액
A19: 2 | B19: 엠지캐피탈 | C19: 3000000000 | E19: 0.012 | F19: =D19+E19/$G$1 -> 0.006 | H19: =C19*E19 -> 36000000
A23: ■통지처
A24: 구분 | B24: 대주명 | C24: 금액 | D24: 통지처
A25: 1 | B25: 키움캐피탈 | C25: 20000000000 | D25: 주소: 서울특별시 영등포구 여의대로 66, 17층 전화번호: 02-780-4295 / 010-4339-3878 팩스번호: 02-780-1517 담당자: 이승근 주임 전자우편: tmd283@kiwoomcapital.com
A26: 2 | B26: 엠지캐피탈 | C26: 10000000000 | D26: 주소: 서울특별시 중구 남대문로 55, MG파이낸스센터 12층 전화번호: 02-2200-7423 / 010-5241-8897 팩스번호: 02-511-3021 담당자: 박소현 과장 전자우편: sopark@mgcap.co.kr
A27: 3 | B27: 디비저축은행 | C27: 8000000000 | D27: 주소: 서울특별시 중구 남대문로 113, 다동 전화번호: 02-3705-1759 / 010-4440-4730 팩스번호: 02-3705-1850 담당자: 정성범 선임 전자우편: seongbeom4730j@dbgroup.co.kr
A28: 합계 | C28: =SUM(C25:C27) -> 38000000000
A30: ■날인페이지
A31: 구분 | B31: 대주명 | C31: 금액
A32: 1 | B32: 키움캐피탈 | C32: 20000000000
A33: 2 | B33: 엠지캐피탈 | C33: 10000000000
A34: 3 | B34: 디비저축은행 | C34: 8000000000
